Workbook
Name Currency: Input!$C$4

Sheet Input
A3: Risk-Free Spot Rates
A4: Maturity | B4: Year | C4: USD
A5: 1 Year | B5: 1 | C5: 0.044490912
A6: 2 Years | B6: =B5+1 -> 2 | C6: 0.043834498
A7: 3 Years | B7: =B6+1 -> 3 | C7: 0.041829148
A8: 4 Years | B8: =B7+1 -> 4 | C8: 0.04063536
A9: 5 Years | B9: =B8+1 -> 5 | C9: 0.039398721
A10: 6 Years | B10: =B9+1 -> 6 | C10: 0.038681191
A11: 7 Years | B11: =B10+1 -> 7 | C11: 0.037930662
A12: 8 Years | B12: =B11+1 -> 8 | C12: 0.037522551
A13: 9 Years | B13: =B12+1 -> 9 | C13: 0.037089294
A14: 10 Years | B14: =B13+1 -> 10 | C14: 0.036634186
A15: 11 Years | B15: =B14+1 -> 11 | C15: 0.036474296
A16: 12 Years | B16: =B15+1 -> 12 | C16: 0.036298089
A17: 13 Years | B17: =B16+1 -> 13 | C17: 0.036107875
... A104: 100 Years | B104: =B103+1 -> 100 | C104: 0.0387163

Sheet Scenario Adjustments
A1: Scenario | B1: Description | C1: 1 Year | D1: 10 Year | E1: 30 Year | F1: Phase-In Period | G1: Phase-Out Period
A2: 0 | B2: Base | C2: 0 | D2: 0 | E2: 0 | F2: 0 | G2: 0
A3: 1 | C3: -0.015 | D3: -0.015 | E3: -0.015 | F3: 10 | G3: 0
A4: =A3+1 -> 2 | C4: 0.015 | D4: 0.015 | E4: 0.015 | F4: 10 | G4: 0
A5: =A4+1 -> 3 | C5: -0.015 | D5: -0.015 | E5: -0.015 | F5: 5 | G5: 5
A6: =A5+1 -> 4 | C6: 0.015 | D6: 0.015 | E6: 0.015 | F6: 5 | G6: 5
A7: =A6+1 -> 5 | C7: -0.015 | D7: -0.01 | E7: -0.005 | F7: 10 | G7: 0
A8: =A7+1 -> 6 | C8: -0.015 | D8: -0.01 | E8: -0.015 | F8: 10 | G8: 0
A9: =A8+1 -> 7 | C9: 0.005 | D9: 0.01 | E9: 0.015 | F9: 10 | G9: 0
A10: =A9+1 -> 8 | C10: 0.015 | D10: 0.01 | E10: 0.005 | F10: 10 | G10: 0

Sheet Reduced Spot Curves
A1: Tenor | I1: 1 | J1: 2 | K1: 3 | L1: 4 | M1: 5 | N1: 6 | O1: 7 | P1: 8 | Q1: 9 | R1: 10 | S1: 11 | T1: 12 | U1: 13 | V1: 14 | W1: 15 | X1: 16 | Y1: 17 | Z1: 18 | AA1: 19 | AB1: 20 | AC1: 21 | AD1: 22 | AE1: 23 | AF1: 24 | AG1: 25 | AH1: 26 | AI1: 27 | AJ1: 28 | AK1: 29 | AL1: 30 | AM1: =AL1+1 -> 31 | AN1: =AM1+1 -> 32 | AO1: =AN1+1 -> 33 | AP1: =AO1+1 -> 34 | AQ1: =AP1+1 -> 35 | AR1: =AQ1+1 -> 36 | AS1: =AR1+1 -> 37 | AT1: =AS1+1 -> 38 | ... DD1: =DC1+1 -> 100
A2: rfr (Spot Curve) | C2: Currency | G2: =MATCH(C5,Input!A4:D4,0) -> #N/A | I2: {=INDEX(Input!$C$5:$C$104,I1,1)} -> 0.044490912 | J2: {=INDEX(Input!$C$5:$C$104,J1,1)} -> 0.043834498 | K2: {=INDEX(Input!$C$5:$C$104,K1,1)} -> 0.041829148 | L2: {=INDEX(Input!$C$5:$C$104,L1,1)} -> 0.04063536 | M2: {=INDEX(Input!$C$5:$C$104,M1,1)} -> 0.039398721 | N2: {=INDEX(Input!$C$5:$C$104,N1,1)} -> 0.038681191 | O2: {=INDEX(Input!$C$5:$C$104,O1,1)} -> 0.037930662 | P2: {=INDEX(Input!$C$5:$C$104,P1,1)} -> 0.037522551 | ... DD2: {=INDEX(Input!$C$5:$C$104,DD1,1)} -> 0.0387163
A3: Forward Curve | I3: =I2 -> 0.044490912 | J3: =((1+J2)^J1)/PRODUCT(1+$I$3:I3)-1 -> 0.043178496 | K3: {=((1+K2)^K1)/PRODUCT(1+$I$3:J3)-1} -> 0.037829998 | L3: {=((1+L2)^L1)/PRODUCT(1+$I$3:K3)-1} -> 0.037062199 | M3: {=((1+M2)^M1)/PRODUCT(1+$I$3:L3)-1} -> 0.034466842 | N3: {=((1+N2)^N1)/PRODUCT(1+$I$3:M3)-1} -> 0.035100965 | O3: {=((1+O2)^O1)/PRODUCT(1+$I$3:N3)-1} -> 0.033438859 | P3: {=((1+P2)^P1)/PRODUCT(1+$I$3:O3)-1} -> 0.034670267 | Q3: {=((1+Q2)^Q1)/PRODUCT(1+$I$3:P3)-1} -> 0.033629743 | R3: {=((1+R2)^R1)/PRODUCT(1+$I$3:Q3)-1} -> 0.032547196 | ... DD3: {=((1+DD2)^DD1)/PRODUCT(1+$I$3:DC3)-1} -> 0.042
I4: =I3+1 -> 1.0444909 | J4: =J3+1 -> 1.0431785 | K4: =K3+1 -> 1.03783 | L4: =L3+1 -> 1.0370622 | M4: =M3+1 -> 1.0344668 | N4: =N3+1 -> 1.035101 | O4: =O3+1 -> 1.0334389 | P4: =P3+1 -> 1.0346703 | ... DD4: =DD3+1 -> 1.042
A5: Currency | C5: US
A6: Scenario #
I7: 1 | J7: =I7-1/9 -> 0.88888889 | K7: =J7-1/9 -> 0.77777778 | L7: =K7-1/9 -> 0.66666667 | M7: =L7-1/9 -> 0.55555556 | N7: =M7-1/9 -> 0.44444444 | O7: =N7-1/9 -> 0.33333333 | P7: =O7-1/9 -> 0.22222222 | Q7: =P7-1/9 -> 0.11111111 | R7: 0 | S7: 0 | T7: 0 | U7: 0 | V7: 0 | W7: 0 | X7: 0 | Y7: 0 | Z7: 0 | AA7: 0 | AB7: 0 | AC7: 0 | AD7: 0 | AE7: 0 | AF7: 0 | AG7: 0 | AH7: 0 | AI7: 0 | AJ7: 0 | AK7: 0 | AL7: 0 | AM7: =AL7 -> 0 | AN7: =AM7 -> 0 | AO7: =AN7 -> 0 | AP7: =AO7 -> 0 | AQ7: =AP7 -> 0 | AR7: =AQ7 -> 0 | AS7: =AR7 -> 0 | AT7: =AS7 -> 0 | ... DD7: =DC7 -> 0
I8: 0 | J8: =I8+1/9 -> 0.11111111 | K8: =J8+1/9 -> 0.22222222 | L8: =K8+1/9 -> 0.33333333 | M8: =L8+1/9 -> 0.44444444 | N8: =M8+1/9 -> 0.55555556 | O8: =N8+1/9 -> 0.66666667 | P8: =O8+1/9 -> 0.77777778 | Q8: =P8+1/9 -> 0.88888889 | R8: 1 | S8: =R8-1/20 -> 0.95 | T8: =S8-1/20 -> 0.9 | U8: =T8-1/20 -> 0.85 | V8: =U8-1/20 -> 0.8 | W8: =V8-1/20 -> 0.75 | X8: =W8-1/20 -> 0.7 | Y8: =X8-1/20 -> 0.65 | Z8: =Y8-1/20 -> 0.6 | ... AK8: =AJ8-1/20 -> 0.05 | AL8: 0 | AM8: =AL8 -> 0 | AN8: =AM8 -> 0 | AO8: =AN8 -> 0 | AP8: =AO8 -> 0 | AQ8: =AP8 -> 0 | AR8: =AQ8 -> 0 | AS8: =AR8 -> 0 | AT8: =AS8 -> 0 | ... DD8: =DC8 -> 0
I9: 0 | J9: 0 | K9: 0 | L9: 0 | M9: 0 | N9: 0 | O9: 0 | P9: 0 | Q9: 0 | R9: 0 | S9: =R9+1/20 -> 0.05 | T9: =S9+1/20 -> 0.1 | U9: =T9+1/20 -> 0.15 | V9: =U9+1/20 -> 0.2 | W9: =V9+1/20 -> 0.25 | X9: =W9+1/20 -> 0.3 | Y9: =X9+1/20 -> 0.35 | Z9: =Y9+1/20 -> 0.4 | ... AK9: =AJ9+1/20 -> 0.95 | AL9: 1 | AM9: =AL9 -> 1 | AN9: =AM9 -> 1 | AO9: =AN9 -> 1 | AP9: =AO9 -> 1 | AQ9: =AP9 -> 1 | AR9: =AQ9 -> 1 | AS9: =AR9 -> 1 | AT9: =AS9 -> 1 | ... DD9: =DC9 -> 1
A12: Tenor | I12: 1 | J12: 2 | K12: 3 | L12: 4 | M12: 5 | N12: 6 | O12: 7 | P12: 8 | Q12: 9 | R12: 10 | S12: 11 | T12: 12 | U12: 13 | V12: 14 | W12: 15 | X12: 16 | Y12: 17 | Z12: 18 | AA12: 19 | AB12: 20 | AC12: 21 | AD12: 22 | AE12: 23 | AF12: 24 | AG12: 25 | AH12: 26 | AI12: 27 | AJ12: 28 | AK12: 29 | AL12: 30 | AM12: 31 | AN12: 32 | AO12: 33 | AP12: 34 | AQ12: 35 | AR12: 36 | AS12: 37 | AT12: 38 | AU12: 39 | AV12: 40 | AW12: 41 | AX12: 42 | AY12: 43 | AZ12: 44 | BA12: 45 | BB12: 46 | BC12: 47 | BD12: 48 | BE12: 49 | BF12: 50 | BG12: 51 | BH12: 52 | BI12: 53 | BJ12: 54 | BK12: 55 | BL12: 56 | BM12: 57 | BN12: 58 | BO12: 59 | BP12: 60 | BQ12: 61 | BR12: 62 | BS12: 63 | BT12: 64 | BU12: 65 | BV12: 66 | BW12: 67 | BX12: 68 | BY12: 69 | BZ12: 70 | CA12: 71 | CB12: 72 | CC12: 73 | CD12: 74 | CE12: 75 | CF12: 76 | CG12: 77 | CH12: 78 | CI12: 79 | CJ12: 80 | CK12: 81 | CL12: 82 | CM12: 83 | CN12: 84 | CO12: 85 | CP12: 86 | CQ12: 87 | CR12: 88 | CS12: 89 | CT12: 90 | CU12: 91 | CV12: 92 | CW12: 93 | CX12: 94 | CY12: 95 | CZ12: 96 | DA12: 97 | DB12: 98 | DC12: 99 | DD12: 100
A13: Year | B13: Scenario # | C13: Month | D13: Time | E13: Adj Short | F13: Adj Med | G13: Adj Long | H13: LookupKey | I13: Forward spot curves
A14: =CEILING(D14/12,1) -> 0 | B14: 0 | C14: =MOD(D14-1,12)+1 -> 12 | D14: 0 | E14: 0 | F14: 0 | G14: 0 | H14: =B14*10000+D14 -> 0 | I14: =IFERROR(PRODUCT(INDEX($I$4:$DD$4,,$A14+1):INDEX($I$4:$DD$4,,I$1+$A14))^(1/I$1)-1,I13) -> 0.044490912 | J14: =IFERROR(PRODUCT(INDEX($I$4:$DD$4,,$A14+1):INDEX($I$4:$DD$4,,J$1+$A14))^(1/J$1)-1,J13) -> 0.043834498 | K14: =IFERROR(PRODUCT(INDEX($I$4:$DD$4,,$A14+1):INDEX($I$4:$DD$4,,K$1+$A14))^(1/K$1)-1,K13) -> 0.041829148 | L14: =IFERROR(PRODUCT(INDEX($I$4:$DD$4,,$A14+1):INDEX($I$4:$DD$4,,L$1+$A14))^(1/L$1)-1,L13) -> 0.04063536 | M14: =IFERROR(PRODUCT(INDEX($I$4:$DD$4,,$A14+1):INDEX($I$4:$DD$4,,M$1+$A14))^(1/M$1)-1,M13) -> 0.039398721 | N14: =IFERROR(PRODUCT(INDEX($I$4:$DD$4,,$A14+1):INDEX($I$4:$DD$4,,N$1+$A14))^(1/N$1)-1,N13) -> 0.038681191 | O14: =IFERROR(PRODUCT(INDEX($I$4:$DD$4,,$A14+1):INDEX($I$4:$DD$4,,O$1+$A14))^(1/O$1)-1,O13) -> 0.037930662 | P14: =IFERROR(PRODUCT(INDEX($I$4:$DD$4,,$A14+1):INDEX($I$4:$DD$4,,P$1+$A14))^(1/P$1)-1,P13) -> 0.037522551 | ... DD14: =IFERROR(PRODUCT(INDEX($I$4:$DD$4,,$A14+1):INDEX($I$4:$DD$4,,DD$1+$A14))^(1/DD$1)-1,DD13) -> 0.0387163
A15: =CEILING(D15/12,1) -> 1 | B15: 0 | C15: 12 | D15: 12 | E15: 0 | F15: 0 | G15: 0 | H15: =B15*10000+D15 -> 12 | I15: =IFERROR(PRODUCT(INDEX($I$4:$DD$4,,$A15+1):INDEX($I$4:$DD$4,,I$1+$A15))^(1/I$1)-1,I14) -> 0.043178496 | J15: =IFERROR(PRODUCT(INDEX($I$4:$DD$4,,$A15+1):INDEX($I$4:$DD$4,,J$1+$A15))^(1/J$1)-1,J14) -> 0.04050081 | K15: =IFERROR(PRODUCT(INDEX($I$4:$DD$4,,$A15+1):INDEX($I$4:$DD$4,,K$1+$A15))^(1/K$1)-1,K14) -> 0.039353342 | L15: =IFERROR(PRODUCT(INDEX($I$4:$DD$4,,$A15+1):INDEX($I$4:$DD$4,,L$1+$A15))^(1/L$1)-1,L14) -> 0.038129557 | M15: =IFERROR(PRODUCT(INDEX($I$4:$DD$4,,$A15+1):INDEX($I$4:$DD$4,,M$1+$A15))^(1/M$1)-1,M14) -> 0.037523131 | N15: =IFERROR(PRODUCT(INDEX($I$4:$DD$4,,$A15+1):INDEX($I$4:$DD$4,,N$1+$A15))^(1/N$1)-1,N14) -> 0.036841299 | O15: =IFERROR(PRODUCT(INDEX($I$4:$DD$4,,$A15+1):INDEX($I$4:$DD$4,,O$1+$A15))^(1/O$1)-1,O14) -> 0.036530873 | P15: =IFERROR(PRODUCT(INDEX($I$4:$DD$4,,$A15+1):INDEX($I$4:$DD$4,,P$1+$A15))^(1/P$1)-1,P14) -> 0.036167787 | ... DD15: =IFERROR(PRODUCT(INDEX($I$4:$DD$4,,$A15+1):INDEX($I$4:$DD$4,,DD$1+$A15))^(1/DD$1)-1,DD14) -> 0.0387163
A16: =A15+1 -> 2 | B16: 0 | C16: 12 | D16: =D15+12 -> 24 | E16: 0 | F16: 0 | G16: 0 | H16: =B16*10000+D16 -> 24 | I16: =IFERROR(PRODUCT(INDEX($I$4:$DD$4,,$A16+1):INDEX($I$4:$DD$4,,I$1+$A16))^(1/I$1)-1,I15) -> 0.037829998 | J16: =IFERROR(PRODUCT(INDEX($I$4:$DD$4,,$A16+1):INDEX($I$4:$DD$4,,J$1+$A16))^(1/J$1)-1,J15) -> 0.037446027 | K16: =IFERROR(PRODUCT(INDEX($I$4:$DD$4,,$A16+1):INDEX($I$4:$DD$4,,K$1+$A16))^(1/K$1)-1,K15) -> 0.036452014 | L16: =IFERROR(PRODUCT(INDEX($I$4:$DD$4,,$A16+1):INDEX($I$4:$DD$4,,L$1+$A16))^(1/L$1)-1,L15) -> 0.036114086 | M16: =IFERROR(PRODUCT(INDEX($I$4:$DD$4,,$A16+1):INDEX($I$4:$DD$4,,M$1+$A16))^(1/M$1)-1,M15) -> 0.035578487 | N16: =IFERROR(PRODUCT(INDEX($I$4:$DD$4,,$A16+1):INDEX($I$4:$DD$4,,N$1+$A16))^(1/N$1)-1,N15) -> 0.035427062 | O16: =IFERROR(PRODUCT(INDEX($I$4:$DD$4,,$A16+1):INDEX($I$4:$DD$4,,O$1+$A16))^(1/O$1)-1,O15) -> 0.035170111 | P16: =IFERROR(PRODUCT(INDEX($I$4:$DD$4,,$A16+1):INDEX($I$4:$DD$4,,P$1+$A16))^(1/P$1)-1,P15) -> 0.034841882 | ... DD16: =IFERROR(PRODUCT(INDEX($I$4:$DD$4,,$A16+1):INDEX($I$4:$DD$4,,DD$1+$A16))^(1/DD$1)-1,DD15) -> 0.0387163
A17: =A16+1 -> 3 | B17: 0 | C17: 12 | D17: =D16+12 -> 36 | E17: 0 | F17: 0 | G17: 0 | H17: =B17*10000+D17 -> 36 | I17: =IFERROR(PRODUCT(INDEX($I$4:$DD$4,,$A17+1):INDEX($I$4:$DD$4,,I$1+$A17))^(1/I$1)-1,I16) -> 0.037062199 | J17: =IFERROR(PRODUCT(INDEX($I$4:$DD$4,,$A17+1):INDEX($I$4:$DD$4,,J$1+$A17))^(1/J$1)-1,J16) -> 0.035763708 | K17: =IFERROR(PRODUCT(INDEX($I$4:$DD$4,,$A17+1):INDEX($I$4:$DD$4,,K$1+$A17))^(1/K$1)-1,K16) -> 0.035542746 | L17: =IFERROR(PRODUCT(INDEX($I$4:$DD$4,,$A17+1):INDEX($I$4:$DD$4,,L$1+$A17))^(1/L$1)-1,L16) -> 0.035016373 | M17: =IFERROR(PRODUCT(INDEX($I$4:$DD$4,,$A17+1):INDEX($I$4:$DD$4,,M$1+$A17))^(1/M$1)-1,M16) -> 0.034947143 | N17: =IFERROR(PRODUCT(INDEX($I$4:$DD$4,,$A17+1):INDEX($I$4:$DD$4,,N$1+$A17))^(1/N$1)-1,N16) -> 0.03472746 | O17: =IFERROR(PRODUCT(INDEX($I$4:$DD$4,,$A17+1):INDEX($I$4:$DD$4,,O$1+$A17))^(1/O$1)-1,O16) -> 0.034415712 | P17: =IFERROR(PRODUCT(INDEX($I$4:$DD$4,,$A17+1):INDEX($I$4:$DD$4,,P$1+$A17))^(1/P$1)-1,P16) -> 0.034473329 | ... DD17: =IFERROR(PRODUCT(INDEX($I$4:$DD$4,,$A17+1):INDEX($I$4:$DD$4,,DD$1+$A17))^(1/DD$1)-1,DD16) -> 0.0387163
A18: =A17+1 -> 4 | B18: 0 | C18: 12 | D18: =D17+12 -> 48 | E18: 0 | F18: 0 | G18: 0 | H18: =B18*10000+D18 -> 48 | I18: =IFERROR(PRODUCT(INDEX($I$4:$DD$4,,$A18+1):INDEX($I$4:$DD$4,,I$1+$A18))^(1/I$1)-1,I17) -> 0.034466842 | J18: =IFERROR(PRODUCT(INDEX($I$4:$DD$4,,$A18+1):INDEX($I$4:$DD$4,,J$1+$A18))^(1/J$1)-1,J17) -> 0.034783855 | K18: =IFERROR(PRODUCT(INDEX($I$4:$DD$4,,$A18+1):INDEX($I$4:$DD$4,,K$1+$A18))^(1/K$1)-1,K17) -> 0.034335329 | L18: =IFERROR(PRODUCT(INDEX($I$4:$DD$4,,$A18+1):INDEX($I$4:$DD$4,,L$1+$A18))^(1/L$1)-1,L17) -> 0.034419053 | M18: =IFERROR(PRODUCT(INDEX($I$4:$DD$4,,$A18+1):INDEX($I$4:$DD$4,,M$1+$A18))^(1/M$1)-1,M17) -> 0.034261143 | N18: =IFERROR(PRODUCT(INDEX($I$4:$DD$4,,$A18+1):INDEX($I$4:$DD$4,,N$1+$A18))^(1/N$1)-1,N17) -> 0.033975288 | O18: =IFERROR(PRODUCT(INDEX($I$4:$DD$4,,$A18+1):INDEX($I$4:$DD$4,,O$1+$A18))^(1/O$1)-1,O17) -> 0.034104019 | P18: =IFERROR(PRODUCT(INDEX($I$4:$DD$4,,$A18+1):INDEX($I$4:$DD$4,,P$1+$A18))^(1/P$1)-1,P17) -> 0.034136237 | ... DD18: =IFERROR(PRODUCT(INDEX($I$4:$DD$4,,$A18+1):INDEX($I$4:$DD$4,,DD$1+$A18))^(1/DD$1)-1,DD17) -> 0.0387163
A19: =A18+1 -> 5 | B19: 0 | C19: 12 | D19: =D18+12 -> 60 | E19: 0 | F19: 0 | G19: 0 | H19: =B19*10000+D19 -> 60 | I19: =IFERROR(PRODUCT(INDEX($I$4:$DD$4,,$A19+1):INDEX($I$4:$DD$4,,I$1+$A19))^(1/I$1)-1,I18) -> 0.035100965 | J19: =IFERROR(PRODUCT(INDEX($I$4:$DD$4,,$A19+1):INDEX($I$4:$DD$4,,J$1+$A19))^(1/J$1)-1,J18) -> 0.034269578 | K19: =IFERROR(PRODUCT(INDEX($I$4:$DD$4,,$A19+1):INDEX($I$4:$DD$4,,K$1+$A19))^(1/K$1)-1,K18) -> 0.034403124 | L19: =IFERROR(PRODUCT(INDEX($I$4:$DD$4,,$A19+1):INDEX($I$4:$DD$4,,L$1+$A19))^(1/L$1)-1,L18) -> 0.034209724 | M19: =IFERROR(PRODUCT(INDEX($I$4:$DD$4,,$A19+1):INDEX($I$4:$DD$4,,M$1+$A19))^(1/M$1)-1,M18) -> 0.033877005 | N19: =IFERROR(PRODUCT(INDEX($I$4:$DD$4,,$A19+1):INDEX($I$4:$DD$4,,N$1+$A19))^(1/N$1)-1,N18) -> 0.034043561 | O19: =IFERROR(PRODUCT(INDEX($I$4:$DD$4,,$A19+1):INDEX($I$4:$DD$4,,O$1+$A19))^(1/O$1)-1,O18) -> 0.034089017 | P19: =IFERROR(PRODUCT(INDEX($I$4:$DD$4,,$A19+1):INDEX($I$4:$DD$4,,P$1+$A19))^(1/P$1)-1,P18) -> 0.034056389 | ... DD19: =IFERROR(PRODUCT(INDEX($I$4:$DD$4,,$A19+1):INDEX($I$4:$DD$4,,DD$1+$A19))^(1/DD$1)-1,DD18) -> 0.0387163
A20: =A19+1 -> 6 | B20: 0 | C20: 12 | D20: =D19+12 -> 72 | E20: 0 | F20: 0 | G20: 0 | H20: =B20*10000+D20 -> 72 | I20: =IFERROR(PRODUCT(INDEX($I$4:$DD$4,,$A20+1):INDEX($I$4:$DD$4,,I$1+$A20))^(1/I$1)-1,I19) -> 0.033438859 | J20: =IFERROR(PRODUCT(INDEX($I$4:$DD$4,,$A20+1):INDEX($I$4:$DD$4,,J$1+$A20))^(1/J$1)-1,J19) -> 0.03405438 | K20: =IFERROR(PRODUCT(INDEX($I$4:$DD$4,,$A20+1):INDEX($I$4:$DD$4,,K$1+$A20))^(1/K$1)-1,K19) -> 0.033912815 | L20: =IFERROR(PRODUCT(INDEX($I$4:$DD$4,,$A20+1):INDEX($I$4:$DD$4,,L$1+$A20))^(1/L$1)-1,L19) -> 0.033571241 | M20: =IFERROR(PRODUCT(INDEX($I$4:$DD$4,,$A20+1):INDEX($I$4:$DD$4,,M$1+$A20))^(1/M$1)-1,M19) -> 0.033832209 | N20: =IFERROR(PRODUCT(INDEX($I$4:$DD$4,,$A20+1):INDEX($I$4:$DD$4,,N$1+$A20))^(1/N$1)-1,N19) -> 0.033920455 | O20: =IFERROR(PRODUCT(INDEX($I$4:$DD$4,,$A20+1):INDEX($I$4:$DD$4,,O$1+$A20))^(1/O$1)-1,O19) -> 0.03390725 | P20: =IFERROR(PRODUCT(INDEX($I$4:$DD$4,,$A20+1):INDEX($I$4:$DD$4,,P$1+$A20))^(1/P$1)-1,P19) -> 0.033828941 | ... DD20: =IFERROR(PRODUCT(INDEX($I$4:$DD$4,,$A20+1):INDEX($I$4:$DD$4,,DD$1+$A20))^(1/DD$1)-1,DD19) -> 0.0387163
A21: =A20+1 -> 7 | B21: 0 | C21: 12 | D21: =D20+12 -> 84 | E21: 0 | F21: 0 | G21: 0 | H21: =B21*10000+D21 -> 84 | I21: =IFERROR(PRODUCT(INDEX($I$4:$DD$4,,$A21+1):INDEX($I$4:$DD$4,,I$1+$A21))^(1/I$1)-1,I20) -> 0.034670267 | J21: =IFERROR(PRODUCT(INDEX($I$4:$DD$4,,$A21+1):INDEX($I$4:$DD$4,,J$1+$A21))^(1/J$1)-1,J20) -> 0.034149874 | K21: =IFERROR(PRODUCT(INDEX($I$4:$DD$4,,$A21+1):INDEX($I$4:$DD$4,,K$1+$A21))^(1/K$1)-1,K20) -> 0.033615372 | L21: =IFERROR(PRODUCT(INDEX($I$4:$DD$4,,$A21+1):INDEX($I$4:$DD$4,,L$1+$A21))^(1/L$1)-1,L20) -> 0.03393057 | M21: =IFERROR(PRODUCT(INDEX($I$4:$DD$4,,$A21+1):INDEX($I$4:$DD$4,,M$1+$A21))^(1/M$1)-1,M20) -> 0.034016801 | N21: =IFERROR(PRODUCT(INDEX($I$4:$DD$4,,$A21+1):INDEX($I$4:$DD$4,,N$1+$A21))^(1/N$1)-1,N20) -> 0.033985336 | O21: =IFERROR(PRODUCT(INDEX($I$4:$DD$4,,$A21+1):INDEX($I$4:$DD$4,,O$1+$A21))^(1/O$1)-1,O20) -> 0.03388468 | P21: =IFERROR(PRODUCT(INDEX($I$4:$DD$4,,$A21+1):INDEX($I$4:$DD$4,,P$1+$A21))^(1/P$1)-1,P20) -> 0.033739668 | ... DD21: =IFERROR(PRODUCT(INDEX($I$4:$DD$4,,$A21+1):INDEX($I$4:$DD$4,,DD$1+$A21))^(1/DD$1)-1,DD20) -> 0.0387163
A22: =A21+1 -> 8 | B22: 0 | C22: 12 | D22: =D21+12 -> 96 | E22: 0 | F22: 0 | G22: 0 | H22: =B22*10000+D22 -> 96 | I22: =IFERROR(PRODUCT(INDEX($I$4:$DD$4,,$A22+1):INDEX($I$4:$DD$4,,I$1+$A22))^(1/I$1)-1,I21) -> 0.033629743 | J22: =IFERROR(PRODUCT(INDEX($I$4:$DD$4,,$A22+1):INDEX($I$4:$DD$4,,J$1+$A22))^(1/J$1)-1,J21) -> 0.033088328 | K22: =IFERROR(PRODUCT(INDEX($I$4:$DD$4,,$A22+1):INDEX($I$4:$DD$4,,K$1+$A22))^(1/K$1)-1,K21) -> 0.033684122 | L22: =IFERROR(PRODUCT(INDEX($I$4:$DD$4,,$A22+1):INDEX($I$4:$DD$4,,L$1+$A22))^(1/L$1)-1,L21) -> 0.033853499 | M22: =IFERROR(PRODUCT(INDEX($I$4:$DD$4,,$A22+1):INDEX($I$4:$DD$4,,M$1+$A22))^(1/M$1)-1,M21) -> 0.033848404 | N22: =IFERROR(PRODUCT(INDEX($I$4:$DD$4,,$A22+1):INDEX($I$4:$DD$4,,N$1+$A22))^(1/N$1)-1,N21) -> 0.033753806 | O22: =IFERROR(PRODUCT(INDEX($I$4:$DD$4,,$A22+1):INDEX($I$4:$DD$4,,O$1+$A22))^(1/O$1)-1,O21) -> 0.033606793 | P22: =IFERROR(PRODUCT(INDEX($I$4:$DD$4,,$A22+1):INDEX($I$4:$DD$4,,P$1+$A22))^(1/P$1)-1,P21) -> 0.033426387 | ... DD22: =IFERROR(PRODUCT(INDEX($I$4:$DD$4,,$A22+1):INDEX($I$4:$DD$4,,DD$1+$A22))^(1/DD$1)-1,DD21) -> 0.0387163
A23: =A22+1 -> 9 | B23: 0 | C23: 12 | D23: =D22+12 -> 108 | E23: 0 | F23: 0 | G23: 0 | H23: =B23*10000+D23 -> 108 | I23: =IFERROR(PRODUCT(INDEX($I$4:$DD$4,,$A23+1):INDEX($I$4:$DD$4,,I$1+$A23))^(1/I$1)-1,I22) -> 0.032547196 | J23: =IFERROR(PRODUCT(INDEX($I$4:$DD$4,,$A23+1):INDEX($I$4:$DD$4,,J$1+$A23))^(1/J$1)-1,J22) -> 0.033711313 | K23: =IFERROR(PRODUCT(INDEX($I$4:$DD$4,,$A23+1):INDEX($I$4:$DD$4,,K$1+$A23))^(1/K$1)-1,K22) -> 0.033928095 | L23: =IFERROR(PRODUCT(INDEX($I$4:$DD$4,,$A23+1):INDEX($I$4:$DD$4,,L$1+$A23))^(1/L$1)-1,L22) -> 0.033903076 | M23: =IFERROR(PRODUCT(INDEX($I$4:$DD$4,,$A23+1):INDEX($I$4:$DD$4,,M$1+$A23))^(1/M$1)-1,M22) -> 0.033778621 | N23: =IFERROR(PRODUCT(INDEX($I$4:$DD$4,,$A23+1):INDEX($I$4:$DD$4,,N$1+$A23))^(1/N$1)-1,N22) -> 0.033602968 | O23: =IFERROR(PRODUCT(INDEX($I$4:$DD$4,,$A23+1):INDEX($I$4:$DD$4,,O$1+$A23))^(1/O$1)-1,O22) -> 0.03339734 | P23: =IFERROR(PRODUCT(INDEX($I$4:$DD$4,,$A23+1):INDEX($I$4:$DD$4,,P$1+$A23))^(1/P$1)-1,P22) -> 0.033172735 | ... DD23: =IFERROR(PRODUCT(INDEX($I$4:$DD$4,,$A23+1):INDEX($I$4:$DD$4,,DD$1+$A23))^(1/DD$1)-1,DD22) -> 0.0387163
A24: =A23+1 -> 10 | B24: 0 | C24: 12 | D24: =D23+12 -> 120 | E24: 0 | F24: 0 | G24: 0 | H24: =B24*10000+D24 -> 120 | I24: =IFERROR(PRODUCT(INDEX($I$4:$DD$4,,$A24+1):INDEX($I$4:$DD$4,,I$1+$A24))^(1/I$1)-1,I23) -> 0.034876743 | J24: =IFERROR(PRODUCT(INDEX($I$4:$DD$4,,$A24+1):INDEX($I$4:$DD$4,,J$1+$A24))^(1/J$1)-1,J23) -> 0.034619237 | K24: =IFERROR(PRODUCT(INDEX($I$4:$DD$4,,$A24+1):INDEX($I$4:$DD$4,,K$1+$A24))^(1/K$1)-1,K23) -> 0.034355432 | L24: =IFERROR(PRODUCT(INDEX($I$4:$DD$4,,$A24+1):INDEX($I$4:$DD$4,,L$1+$A24))^(1/L$1)-1,L23) -> 0.034086706 | M24: =IFERROR(PRODUCT(INDEX($I$4:$DD$4,,$A24+1):INDEX($I$4:$DD$4,,M$1+$A24))^(1/M$1)-1,M23) -> 0.033814252 | N24: =IFERROR(PRODUCT(INDEX($I$4:$DD$4,,$A24+1):INDEX($I$4:$DD$4,,N$1+$A24))^(1/N$1)-1,N23) -> 0.033539098 | O24: =IFERROR(PRODUCT(INDEX($I$4:$DD$4,,$A24+1):INDEX($I$4:$DD$4,,O$1+$A24))^(1/O$1)-1,O23) -> 0.033262128 | P24: =IFERROR(PRODUCT(INDEX($I$4:$DD$4,,$A24+1):INDEX($I$4:$DD$4,,P$1+$A24))^(1/P$1)-1,P23) -> 0.032984098 | ... DD24: =IFERROR(PRODUCT(INDEX($I$4:$DD$4,,$A24+1):INDEX($I$4:$DD$4,,DD$1+$A24))^(1/DD$1)-1,DD23) -> 0.0387163
A25: =A24+1 -> 11 | B25: 0 | C25: 12 | D25: =D24+12 -> 132 | E25: 0 | F25: 0 | G25: 0 | H25: =B25*10000+D25 -> 132 | I25: =IFERROR(PRODUCT(INDEX($I$4:$DD$4,,$A25+1):INDEX($I$4:$DD$4,,I$1+$A25))^(1/I$1)-1,I24) -> 0.034361794 | J25: =IFERROR(PRODUCT(INDEX($I$4:$DD$4,,$A25+1):INDEX($I$4:$DD$4,,J$1+$A25))^(1/J$1)-1,J24) -> 0.034094875 | K25: =IFERROR(PRODUCT(INDEX($I$4:$DD$4,,$A25+1):INDEX($I$4:$DD$4,,K$1+$A25))^(1/K$1)-1,K24) -> 0.033823495 | L25: =IFERROR(PRODUCT(INDEX($I$4:$DD$4,,$A25+1):INDEX($I$4:$DD$4,,L$1+$A25))^(1/L$1)-1,L24) -> 0.0335488 | M25: =IFERROR(PRODUCT(INDEX($I$4:$DD$4,,$A25+1):INDEX($I$4:$DD$4,,M$1+$A25))^(1/M$1)-1,M24) -> 0.033271777 | N25: =IFERROR(PRODUCT(INDEX($I$4:$DD$4,,$A25+1):INDEX($I$4:$DD$4,,N$1+$A25))^(1/N$1)-1,N24) -> 0.032993271 | O25: =IFERROR(PRODUCT(INDEX($I$4:$DD$4,,$A25+1):INDEX($I$4:$DD$4,,O$1+$A25))^(1/O$1)-1,O24) -> 0.032714003 | P25: =IFERROR(PRODUCT(INDEX($I$4:$DD$4,,$A25+1):INDEX($I$4:$DD$4,,P$1+$A25))^(1/P$1)-1,P24) -> 0.032434581 | ... DD25: =IFERROR(PRODUCT(INDEX($I$4:$DD$4,,$A25+1):INDEX($I$4:$DD$4,,DD$1+$A25))^(1/DD$1)-1,DD24) -> 0.0387163
A26: =A25+1 -> 12 | B26: 0 | C26: 12 | D26: =D25+12 -> 144 | E26: 0 | F26: 0 | G26: 0 | H26: =B26*10000+D26 -> 144 | I26: =IFERROR(PRODUCT(INDEX($I$4:$DD$4,,$A26+1):INDEX($I$4:$DD$4,,I$1+$A26))^(1/I$1)-1,I25) -> 0.033828024 | J26: =IFERROR(PRODUCT(INDEX($I$4:$DD$4,,$A26+1):INDEX($I$4:$DD$4,,J$1+$A26))^(1/J$1)-1,J25) -> 0.03355445 | K26: =IFERROR(PRODUCT(INDEX($I$4:$DD$4,,$A26+1):INDEX($I$4:$DD$4,,K$1+$A26))^(1/K$1)-1,K25) -> 0.033277944 | L26: =IFERROR(PRODUCT(INDEX($I$4:$DD$4,,$A26+1):INDEX($I$4:$DD$4,,L$1+$A26))^(1/L$1)-1,L25) -> 0.032999452 | M26: =IFERROR(PRODUCT(INDEX($I$4:$DD$4,,$A26+1):INDEX($I$4:$DD$4,,M$1+$A26))^(1/M$1)-1,M25) -> 0.032719783 | N26: =IFERROR(PRODUCT(INDEX($I$4:$DD$4,,$A26+1):INDEX($I$4:$DD$4,,N$1+$A26))^(1/N$1)-1,N25) -> 0.032439626 | O26: =IFERROR(PRODUCT(INDEX($I$4:$DD$4,,$A26+1):INDEX($I$4:$DD$4,,O$1+$A26))^(1/O$1)-1,O25) -> 0.032159558 | P26: =IFERROR(PRODUCT(INDEX($I$4:$DD$4,,$A26+1):INDEX($I$4:$DD$4,,P$1+$A26))^(1/P$1)-1,P25) -> 0.031880062 | ... DD26: =IFERROR(PRODUCT(INDEX($I$4:$DD$4,,$A26+1):INDEX($I$4:$DD$4,,DD$1+$A26))^(1/DD$1)-1,DD25) -> 0.0387163
A27: =A26+1 -> 13 | B27: 0 | C27: 12 | D27: =D26+12 -> 156 | E27: 0 | F27: 0 | G27: 0 | H27: =B27*10000+D27 -> 156 | I27: =IFERROR(PRODUCT(INDEX($I$4:$DD$4,,$A27+1):INDEX($I$4:$DD$4,,I$1+$A27))^(1/I$1)-1,I26) -> 0.033280949 | J27: =IFERROR(PRODUCT(INDEX($I$4:$DD$4,,$A27+1):INDEX($I$4:$DD$4,,J$1+$A27))^(1/J$1)-1,J26) -> 0.033003014 | K27: =IFERROR(PRODUCT(INDEX($I$4:$DD$4,,$A27+1):INDEX($I$4:$DD$4,,K$1+$A27))^(1/K$1)-1,K26) -> 0.032723409 | L27: =IFERROR(PRODUCT(INDEX($I$4:$DD$4,,$A27+1):INDEX($I$4:$DD$4,,L$1+$A27))^(1/L$1)-1,L26) -> 0.032442909 | M27: =IFERROR(PRODUCT(INDEX($I$4:$DD$4,,$A27+1):INDEX($I$4:$DD$4,,M$1+$A27))^(1/M$1)-1,M26) -> 0.03216217 | N27: =IFERROR(PRODUCT(INDEX($I$4:$DD$4,,$A27+1):INDEX($I$4:$DD$4,,N$1+$A27))^(1/N$1)-1,N26) -> 0.031881742 | O27: =IFERROR(PRODUCT(INDEX($I$4:$DD$4,,$A27+1):INDEX($I$4:$DD$4,,O$1+$A27))^(1/O$1)-1,O26) -> 0.031602081 | P27: =IFERROR(PRODUCT(INDEX($I$4:$DD$4,,$A27+1):INDEX($I$4:$DD$4,,P$1+$A27))^(1/P$1)-1,P26) -> 0.030885291 | ... DD27: =IFERROR(PRODUCT(INDEX($I$4:$DD$4,,$A27+1):INDEX($I$4:$DD$4,,DD$1+$A27))^(1/DD$1)-1,DD26) -> 0.0387163
... A114: =A113+1 -> 100 | B114: 0 | C114: 12 | D114: =D113+12 -> 1200 | E114: 0 | F114: 0 | G114: 0 | H114: =B114*10000+D114 -> 1200 | I114: =IFERROR(PRODUCT(INDEX($I$4:$DD$4,,$A114+1):INDEX($I$4:$DD$4,,I$1+$A114))^(1/I$1)-1,I113) -> 0.042 | J114: =IFERROR(PRODUCT(INDEX($I$4:$DD$4,,$A114+1):INDEX($I$4:$DD$4,,J$1+$A114))^(1/J$1)-1,J113) -> 0.042 | K114: =IFERROR(PRODUCT(INDEX($I$4:$DD$4,,$A114+1):INDEX($I$4:$DD$4,,K$1+$A114))^(1/K$1)-1,K113) -> 0.042 | L114: =IFERROR(PRODUCT(INDEX($I$4:$DD$4,,$A114+1):INDEX($I$4:$DD$4,,L$1+$A114))^(1/L$1)-1,L113) -> 0.042 | M114: =IFERROR(PRODUCT(INDEX($I$4:$DD$4,,$A114+1):INDEX($I$4:$DD$4,,M$1+$A114))^(1/M$1)-1,M113) -> 0.042 | N114: =IFERROR(PRODUCT(INDEX($I$4:$DD$4,,$A114+1):INDEX($I$4:$DD$4,,N$1+$A114))^(1/N$1)-1,N113) -> 0.042 | O114: =IFERROR(PRODUCT(INDEX($I$4:$DD$4,,$A114+1):INDEX($I$4:$DD$4,,O$1+$A114))^(1/O$1)-1,O113) -> 0.042 | P114: =IFERROR(PRODUCT(INDEX($I$4:$DD$4,,$A114+1):INDEX($I$4:$DD$4,,P$1+$A114))^(1/P$1)-1,P113) -> 0.042 | ... DD114: =IFERROR(PRODUCT(INDEX($I$4:$DD$4,,$A114+1):INDEX($I$4:$DD$4,,DD$1+$A114))^(1/DD$1)-1,DD113) -> 0.0387163
A115: =A14 -> 0 | B115: =B14+1 -> 1 | C115: =C14 -> 12 | D115: =D14 -> 0 | E115: 0 | F115: 0 | G115: 0 | H115: =B115*10000+D115 -> 10000 | I115: {=INDEX(I$14:I$114,$A115+1)+SUMPRODUCT(TRANSPOSE($E115:$G115),I$7:I$9)} -> 0.044490912 | J115: {=INDEX(J$14:J$114,$A115+1)+SUMPRODUCT(TRANSPOSE($E115:$G115),J$7:J$9)} -> 0.043834498 | K115: {=INDEX(K$14:K$114,$A115+1)+SUMPRODUCT(TRANSPOSE($E115:$G115),K$7:K$9)} -> 0.041829148 | L115: {=INDEX(L$14:L$114,$A115+1)+SUMPRODUCT(TRANSPOSE($E115:$G115),L$7:L$9)} -> 0.04063536 | M115: {=INDEX(M$14:M$114,$A115+1)+SUMPRODUCT(TRANSPOSE($E115:$G115),M$7:M$9)} -> 0.039398721 | N115: {=INDEX(N$14:N$114,$A115+1)+SUMPRODUCT(TRANSPOSE($E115:$G115),N$7:N$9)} -> 0.038681191 | O115: {=INDEX(O$14:O$114,$A115+1)+SUMPRODUCT(TRANSPOSE($E115:$G115),O$7:O$9)} -> 0.037930662 | P115: {=INDEX(P$14:P$114,$A115+1)+SUMPRODUCT(TRANSPOSE($E115:$G115),P$7:P$9)} -> 0.037522551 | ... DD115: {=INDEX(DD$14:DD$114,$A115+1)+SUMPRODUCT(TRANSPOSE($E115:$G115),DD$7:DD$9)} -> 0.0387163
A116: =A15 -> 1 | B116: =B15+1 -> 1 | C116: =C15 -> 12 | D116: =D15 -> 12 | E116: =E115-0.0015 -> -0.0015 | F116: =F115-0.0015 -> -0.0015 | G116: =G115-0.0015 -> -0.0015 | H116: =B116*10000+D116 -> 10012 | I116: {=INDEX(I$14:I$114,$A116+1)+SUMPRODUCT(TRANSPOSE($E116:$G116),I$7:I$9)} -> 0.041678496 | J116: {=INDEX(J$14:J$114,$A116+1)+SUMPRODUCT(TRANSPOSE($E116:$G116),J$7:J$9)} -> 0.03900081 | K116: {=INDEX(K$14:K$114,$A116+1)+SUMPRODUCT(TRANSPOSE($E116:$G116),K$7:K$9)} -> 0.037853342 | L116: {=INDEX(L$14:L$114,$A116+1)+SUMPRODUCT(TRANSPOSE($E116:$G116),L$7:L$9)} -> 0.036629557 | M116: {=INDEX(M$14:M$114,$A116+1)+SUMPRODUCT(TRANSPOSE($E116:$G116),M$7:M$9)} -> 0.036023131 | N116: {=INDEX(N$14:N$114,$A116+1)+SUMPRODUCT(TRANSPOSE($E116:$G116),N$7:N$9)} -> 0.035341299 | O116: {=INDEX(O$14:O$114,$A116+1)+SUMPRODUCT(TRANSPOSE($E116:$G116),O$7:O$9)} -> 0.035030873 | P116: {=INDEX(P$14:P$114,$A116+1)+SUMPRODUCT(TRANSPOSE($E116:$G116),P$7:P$9)} -> 0.034667787 | ... DD116: {=INDEX(DD$14:DD$114,$A116+1)+SUMPRODUCT(TRANSPOSE($E116:$G116),DD$7:DD$9)} -> 0.0372163
A117: =A16 -> 2 | B117: =B16+1 -> 1 | C117: =C16 -> 12 | D117: =D16 -> 24 | E117: =E116-0.0015 -> -0.003 | F117: =F116-0.0015 -> -0.003 | G117: =G116-0.0015 -> -0.003 | H117: =B117*10000+D117 -> 10024 | I117: {=INDEX(I$14:I$114,$A117+1)+SUMPRODUCT(TRANSPOSE($E117:$G117),I$7:I$9)} -> 0.034829998 | J117: {=INDEX(J$14:J$114,$A117+1)+SUMPRODUCT(TRANSPOSE($E117:$G117),J$7:J$9)} -> 0.034446027 | K117: {=INDEX(K$14:K$114,$A117+1)+SUMPRODUCT(TRANSPOSE($E117:$G117),K$7:K$9)} -> 0.033452014 | L117: {=INDEX(L$14:L$114,$A117+1)+SUMPRODUCT(TRANSPOSE($E117:$G117),L$7:L$9)} -> 0.033114086 | M117: {=INDEX(M$14:M$114,$A117+1)+SUMPRODUCT(TRANSPOSE($E117:$G117),M$7:M$9)} -> 0.032578487 | N117: {=INDEX(N$14:N$114,$A117+1)+SUMPRODUCT(TRANSPOSE($E117:$G117),N$7:N$9)} -> 0.032427062 | O117: {=INDEX(O$14:O$114,$A117+1)+SUMPRODUCT(TRANSPOSE($E117:$G117),O$7:O$9)} -> 0.032170111 | P117: {=INDEX(P$14:P$114,$A117+1)+SUMPRODUCT(TRANSPOSE($E117:$G117),P$7:P$9)} -> 0.031841882 | ... DD117: {=INDEX(DD$14:DD$114,$A117+1)+SUMPRODUCT(TRANSPOSE($E117:$G117),DD$7:DD$9)} -> 0.0357163
A118: =A17 -> 3 | B118: =B17+1 -> 1 | C118: =C17 -> 12 | D118: =D17 -> 36 | E118: =E117-0.0015 -> -0.0045 | F118: =F117-0.0015 -> -0.0045 | G118: =G117-0.0015 -> -0.0045 | H118: =B118*10000+D118 -> 10036 | I118: {=INDEX(I$14:I$114,$A118+1)+SUMPRODUCT(TRANSPOSE($E118:$G118),I$7:I$9)} -> 0.032562199 | J118: {=INDEX(J$14:J$114,$A118+1)+SUMPRODUCT(TRANSPOSE($E118:$G118),J$7:J$9)} -> 0.031263708 | K118: {=INDEX(K$14:K$114,$A118+1)+SUMPRODUCT(TRANSPOSE($E118:$G118),K$7:K$9)} -> 0.031042746 | L118: {=INDEX(L$14:L$114,$A118+1)+SUMPRODUCT(TRANSPOSE($E118:$G118),L$7:L$9)} -> 0.030516373 | M118: {=INDEX(M$14:M$114,$A118+1)+SUMPRODUCT(TRANSPOSE($E118:$G118),M$7:M$9)} -> 0.030447143 | N118: {=INDEX(N$14:N$114,$A118+1)+SUMPRODUCT(TRANSPOSE($E118:$G118),N$7:N$9)} -> 0.03022746 | O118: {=INDEX(O$14:O$114,$A118+1)+SUMPRODUCT(TRANSPOSE($E118:$G118),O$7:O$9)} -> 0.029915712 | P118: {=INDEX(P$14:P$114,$A118+1)+SUMPRODUCT(TRANSPOSE($E118:$G118),P$7:P$9)} -> 0.029973329 | ... DD118: {=INDEX(DD$14:DD$114,$A118+1)+SUMPRODUCT(TRANSPOSE($E118:$G118),DD$7:DD$9)} -> 0.0342163
A119: =A18 -> 4 | B119: =B18+1 -> 1 | C119: =C18 -> 12 | D119: =D18 -> 48 | E119: =E118-0.0015 -> -0.006 | F119: =F118-0.0015 -> -0.006 | G119: =G118-0.0015 -> -0.006 | H119: =B119*10000+D119 -> 10048 | I119: {=INDEX(I$14:I$114,$A119+1)+SUMPRODUCT(TRANSPOSE($E119:$G119),I$7:I$9)} -> 0.028466842 | J119: {=INDEX(J$14:J$114,$A119+1)+SUMPRODUCT(TRANSPOSE($E119:$G119),J$7:J$9)} -> 0.028783855 | K119: {=INDEX(K$14:K$114,$A119+1)+SUMPRODUCT(TRANSPOSE($E119:$G119),K$7:K$9)} -> 0.028335329 | L119: {=INDEX(L$14:L$114,$A119+1)+SUMPRODUCT(TRANSPOSE($E119:$G119),L$7:L$9)} -> 0.028419053 | M119: {=INDEX(M$14:M$114,$A119+1)+SUMPRODUCT(TRANSPOSE($E119:$G119),M$7:M$9)} -> 0.028261143 | N119: {=INDEX(N$14:N$114,$A119+1)+SUMPRODUCT(TRANSPOSE($E119:$G119),N$7:N$9)} -> 0.027975288 | O119: {=INDEX(O$14:O$114,$A119+1)+SUMPRODUCT(TRANSPOSE($E119:$G119),O$7:O$9)} -> 0.028104019 | P119: {=INDEX(P$14:P$114,$A119+1)+SUMPRODUCT(TRANSPOSE($E119:$G119),P$7:P$9)} -> 0.028136237 | ... DD119: {=INDEX(DD$14:DD$114,$A119+1)+SUMPRODUCT(TRANSPOSE($E119:$G119),DD$7:DD$9)} -> 0.0327163
A120: =A19 -> 5 | B120: =B19+1 -> 1 | C120: =C19 -> 12 | D120: =D19 -> 60 | E120: =E119-0.0015 -> -0.0075 | F120: =F119-0.0015 -> -0.0075 | G120: =G119-0.0015 -> -0.0075 | H120: =B120*10000+D120 -> 10060 | I120: {=INDEX(I$14:I$114,$A120+1)+SUMPRODUCT(TRANSPOSE($E120:$G120),I$7:I$9)} -> 0.027600965 | J120: {=INDEX(J$14:J$114,$A120+1)+SUMPRODUCT(TRANSPOSE($E120:$G120),J$7:J$9)} -> 0.026769578 | K120: {=INDEX(K$14:K$114,$A120+1)+SUMPRODUCT(TRANSPOSE($E120:$G120),K$7:K$9)} -> 0.026903124 | L120: {=INDEX(L$14:L$114,$A120+1)+SUMPRODUCT(TRANSPOSE($E120:$G120),L$7:L$9)} -> 0.026709724 | M120: {=INDEX(M$14:M$114,$A120+1)+SUMPRODUCT(TRANSPOSE($E120:$G120),M$7:M$9)} -> 0.026377005 | N120: {=INDEX(N$14:N$114,$A120+1)+SUMPRODUCT(TRANSPOSE($E120:$G120),N$7:N$9)} -> 0.026543561 | O120: {=INDEX(O$14:O$114,$A120+1)+SUMPRODUCT(TRANSPOSE($E120:$G120),O$7:O$9)} -> 0.026589017 | P120: {=INDEX(P$14:P$114,$A120+1)+SUMPRODUCT(TRANSPOSE($E120:$G120),P$7:P$9)} -> 0.026556389 | ... DD120: {=INDEX(DD$14:DD$114,$A120+1)+SUMPRODUCT(TRANSPOSE($E120:$G120),DD$7:DD$9)} -> 0.0312163
A121: =A20 -> 6 | B121: =B20+1 -> 1 | C121: =C20 -> 12 | D121: =D20 -> 72 | E121: =E120-0.0015 -> -0.009 | F121: =F120-0.0015 -> -0.009 | G121: =G120-0.0015 -> -0.009 | H121: =B121*10000+D121 -> 10072 | I121: {=INDEX(I$14:I$114,$A121+1)+SUMPRODUCT(TRANSPOSE($E121:$G121),I$7:I$9)} -> 0.024438859 | J121: {=INDEX(J$14:J$114,$A121+1)+SUMPRODUCT(TRANSPOSE($E121:$G121),J$7:J$9)} -> 0.02505438 | K121: {=INDEX(K$14:K$114,$A121+1)+SUMPRODUCT(TRANSPOSE($E121:$G121),K$7:K$9)} -> 0.024912815 | L121: {=INDEX(L$14:L$114,$A121+1)+SUMPRODUCT(TRANSPOSE($E121:$G121),L$7:L$9)} -> 0.024571241 | M121: {=INDEX(M$14:M$114,$A121+1)+SUMPRODUCT(TRANSPOSE($E121:$G121),M$7:M$9)} -> 0.024832209 | N121: {=INDEX(N$14:N$114,$A121+1)+SUMPRODUCT(TRANSPOSE($E121:$G121),N$7:N$9)} -> 0.024920455 | O121: {=INDEX(O$14:O$114,$A121+1)+SUMPRODUCT(TRANSPOSE($E121:$G121),O$7:O$9)} -> 0.02490725 | P121: {=INDEX(P$14:P$114,$A121+1)+SUMPRODUCT(TRANSPOSE($E121:$G121),P$7:P$9)} -> 0.024828941 | ... DD121: {=INDEX(DD$14:DD$114,$A121+1)+SUMPRODUCT(TRANSPOSE($E121:$G121),DD$7:DD$9)} -> 0.0297163
A122: =A21 -> 7 | B122: =B21+1 -> 1 | C122: =C21 -> 12 | D122: =D21 -> 84 | E122: =E121-0.0015 -> -0.0105 | F122: =F121-0.0015 -> -0.0105 | G122: =G121-0.0015 -> -0.0105 | H122: =B122*10000+D122 -> 10084 | I122: {=INDEX(I$14:I$114,$A122+1)+SUMPRODUCT(TRANSPOSE($E122:$G122),I$7:I$9)} -> 0.024170267 | J122: {=INDEX(J$14:J$114,$A122+1)+SUMPRODUCT(TRANSPOSE($E122:$G122),J$7:J$9)} -> 0.023649874 | K122: {=INDEX(K$14:K$114,$A122+1)+SUMPRODUCT(TRANSPOSE($E122:$G122),K$7:K$9)} -> 0.023115372 | L122: {=INDEX(L$14:L$114,$A122+1)+SUMPRODUCT(TRANSPOSE($E122:$G122),L$7:L$9)} -> 0.02343057 | M122: {=INDEX(M$14:M$114,$A122+1)+SUMPRODUCT(TRANSPOSE($E122:$G122),M$7:M$9)} -> 0.023516801 | N122: {=INDEX(N$14:N$114,$A122+1)+SUMPRODUCT(TRANSPOSE($E122:$G122),N$7:N$9)} -> 0.023485336 | O122: {=INDEX(O$14:O$114,$A122+1)+SUMPRODUCT(TRANSPOSE($E122:$G122),O$7:O$9)} -> 0.02338468 | P122: {=INDEX(P$14:P$114,$A122+1)+SUMPRODUCT(TRANSPOSE($E122:$G122),P$7:P$9)} -> 0.023239668 | ... DD122: {=INDEX(DD$14:DD$114,$A122+1)+SUMPRODUCT(TRANSPOSE($E122:$G122),DD$7:DD$9)} -> 0.0282163
A123: =A22 -> 8 | B123: =B22+1 -> 1 | C123: =C22 -> 12 | D123: =D22 -> 96 | E123: =E122-0.0015 -> -0.012 | F123: =F122-0.0015 -> -0.012 | G123: =G122-0.0015 -> -0.012 | H123: =B123*10000+D123 -> 10096 | I123: {=INDEX(I$14:I$114,$A123+1)+SUMPRODUCT(TRANSPOSE($E123:$G123),I$7:I$9)} -> 0.021629743 | J123: {=INDEX(J$14:J$114,$A123+1)+SUMPRODUCT(TRANSPOSE($E123:$G123),J$7:J$9)} -> 0.021088328 | K123: {=INDEX(K$14:K$114,$A123+1)+SUMPRODUCT(TRANSPOSE($E123:$G123),K$7:K$9)} -> 0.021684122 | L123: {=INDEX(L$14:L$114,$A123+1)+SUMPRODUCT(TRANSPOSE($E123:$G123),L$7:L$9)} -> 0.021853499 | M123: {=INDEX(M$14:M$114,$A123+1)+SUMPRODUCT(TRANSPOSE($E123:$G123),M$7:M$9)} -> 0.021848404 | N123: {=INDEX(N$14:N$114,$A123+1)+SUMPRODUCT(TRANSPOSE($E123:$G123),N$7:N$9)} -> 0.021753806 | O123: {=INDEX(O$14:O$114,$A123+1)+SUMPRODUCT(TRANSPOSE($E123:$G123),O$7:O$9)} -> 0.021606793 | P123: {=INDEX(P$14:P$114,$A123+1)+SUMPRODUCT(TRANSPOSE($E123:$G123),P$7:P$9)} -> 0.021426387 | ... DD123: {=INDEX(DD$14:DD$114,$A123+1)+SUMPRODUCT(TRANSPOSE($E123:$G123),DD$7:DD$9)} -> 0.0267163
A124: =A23 -> 9 | B124: =B23+1 -> 1 | C124: =C23 -> 12 | D124: =D23 -> 108 | E124: =E123-0.0015 -> -0.0135 | F124: =F123-0.0015 -> -0.0135 | G124: =G123-0.0015 -> -0.0135 | H124: =B124*10000+D124 -> 10108 | I124: {=INDEX(I$14:I$114,$A124+1)+SUMPRODUCT(TRANSPOSE($E124:$G124),I$7:I$9)} -> 0.019047196 | J124: {=INDEX(J$14:J$114,$A124+1)+SUMPRODUCT(TRANSPOSE($E124:$G124),J$7:J$9)} -> 0.020211313 | K124: {=INDEX(K$14:K$114,$A124+1)+SUMPRODUCT(TRANSPOSE($E124:$G124),K$7:K$9)} -> 0.020428095 | L124: {=INDEX(L$14:L$114,$A124+1)+SUMPRODUCT(TRANSPOSE($E124:$G124),L$7:L$9)} -> 0.020403076 | M124: {=INDEX(M$14:M$114,$A124+1)+SUMPRODUCT(TRANSPOSE($E124:$G124),M$7:M$9)} -> 0.020278621 | N124: {=INDEX(N$14:N$114,$A124+1)+SUMPRODUCT(TRANSPOSE($E124:$G124),N$7:N$9)} -> 0.020102968 | O124: {=INDEX(O$14:O$114,$A124+1)+SUMPRODUCT(TRANSPOSE($E124:$G124),O$7:O$9)} -> 0.01989734 | P124: {=INDEX(P$14:P$114,$A124+1)+SUMPRODUCT(TRANSPOSE($E124:$G124),P$7:P$9)} -> 0.019672735 | ... DD124: {=INDEX(DD$14:DD$114,$A124+1)+SUMPRODUCT(TRANSPOSE($E124:$G124),DD$7:DD$9)} -> 0.0252163
A125: =A24 -> 10 | B125: =B24+1 -> 1 | C125: =C24 -> 12 | D125: =D24 -> 120 | E125: =E124-0.0015 -> -0.015 | F125: =F124-0.0015 -> -0.015 | G125: =G124-0.0015 -> -0.015 | H125: =B125*10000+D125 -> 10120 | I125: {=INDEX(I$14:I$114,$A125+1)+SUMPRODUCT(TRANSPOSE($E125:$G125),I$7:I$9)} -> 0.019876743 | J125: {=INDEX(J$14:J$114,$A125+1)+SUMPRODUCT(TRANSPOSE($E125:$G125),J$7:J$9)} -> 0.019619237 | K125: {=INDEX(K$14:K$114,$A125+1)+SUMPRODUCT(TRANSPOSE($E125:$G125),K$7:K$9)} -> 0.019355432 | L125: {=INDEX(L$14:L$114,$A125+1)+SUMPRODUCT(TRANSPOSE($E125:$G125),L$7:L$9)} -> 0.019086706 | M125: {=INDEX(M$14:M$114,$A125+1)+SUMPRODUCT(TRANSPOSE($E125:$G125),M$7:M$9)} -> 0.018814252 | N125: {=INDEX(N$14:N$114,$A125+1)+SUMPRODUCT(TRANSPOSE($E125:$G125),N$7:N$9)} -> 0.018539098 | O125: {=INDEX(O$14:O$114,$A125+1)+SUMPRODUCT(TRANSPOSE($E125:$G125),O$7:O$9)} -> 0.018262128 | P125: {=INDEX(P$14:P$114,$A125+1)+SUMPRODUCT(TRANSPOSE($E125:$G125),P$7:P$9)} -> 0.017984098 | ... DD125: {=INDEX(DD$14:DD$114,$A125+1)+SUMPRODUCT(TRANSPOSE($E125:$G125),DD$7:DD$9)} -> 0.0237163
A126: =A25 -> 11 | B126: =B25+1 -> 1 | C126: =C25 -> 12 | D126: =D25 -> 132 | E126: =E125 -> -0.015 | F126: =F125 -> -0.015 | G126: =G125 -> -0.015 | H126: =B126*10000+D126 -> 10132 | I126: {=INDEX(I$14:I$114,$A126+1)+SUMPRODUCT(TRANSPOSE($E126:$G126),I$7:I$9)} -> 0.019361794 | J126: {=INDEX(J$14:J$114,$A126+1)+SUMPRODUCT(TRANSPOSE($E126:$G126),J$7:J$9)} -> 0.019094875 | K126: {=INDEX(K$14:K$114,$A126+1)+SUMPRODUCT(TRANSPOSE($E126:$G126),K$7:K$9)} -> 0.018823495 | L126: {=INDEX(L$14:L$114,$A126+1)+SUMPRODUCT(TRANSPOSE($E126:$G126),L$7:L$9)} -> 0.0185488 | M126: {=INDEX(M$14:M$114,$A126+1)+SUMPRODUCT(TRANSPOSE($E126:$G126),M$7:M$9)} -> 0.018271777 | N126: {=INDEX(N$14:N$114,$A126+1)+SUMPRODUCT(TRANSPOSE($E126:$G126),N$7:N$9)} -> 0.017993271 | O126: {=INDEX(O$14:O$114,$A126+1)+SUMPRODUCT(TRANSPOSE($E126:$G126),O$7:O$9)} -> 0.017714003 | P126: {=INDEX(P$14:P$114,$A126+1)+SUMPRODUCT(TRANSPOSE($E126:$G126),P$7:P$9)} -> 0.017434581 | ... DD126: {=INDEX(DD$14:DD$114,$A126+1)+SUMPRODUCT(TRANSPOSE($E126:$G126),DD$7:DD$9)} -> 0.0237163
A127: =A26 -> 12 | B127: =B26+1 -> 1 | C127: =C26 -> 12 | D127: =D26 -> 144 | E127: =E126 -> -0.015 | F127: =F126 -> -0.015 | G127: =G126 -> -0.015 | H127: =B127*10000+D127 -> 10144 | I127: {=INDEX(I$14:I$114,$A127+1)+SUMPRODUCT(TRANSPOSE($E127:$G127),I$7:I$9)} -> 0.018828024 | J127: {=INDEX(J$14:J$114,$A127+1)+SUMPRODUCT(TRANSPOSE($E127:$G127),J$7:J$9)} -> 0.01855445 | K127: {=INDEX(K$14:K$114,$A127+1)+SUMPRODUCT(TRANSPOSE($E127:$G127),K$7:K$9)} -> 0.018277944 | L127: {=INDEX(L$14:L$114,$A127+1)+SUMPRODUCT(TRANSPOSE($E127:$G127),L$7:L$9)} -> 0.017999452 | M127: {=INDEX(M$14:M$114,$A127+1)+SUMPRODUCT(TRANSPOSE($E127:$G127),M$7:M$9)} -> 0.017719783 | N127: {=INDEX(N$14:N$114,$A127+1)+SUMPRODUCT(TRANSPOSE($E127:$G127),N$7:N$9)} -> 0.017439626 | O127: {=INDEX(O$14:O$114,$A127+1)+SUMPRODUCT(TRANSPOSE($E127:$G127),O$7:O$9)} -> 0.017159558 | P127: {=INDEX(P$14:P$114,$A127+1)+SUMPRODUCT(TRANSPOSE($E127:$G127),P$7:P$9)} -> 0.016880062 | ... DD127: {=INDEX(DD$14:DD$114,$A127+1)+SUMPRODUCT(TRANSPOSE($E127:$G127),DD$7:DD$9)} -> 0.0237163
A128: =A27 -> 13 | B128: =B27+1 -> 1 | C128: =C27 -> 12 | D128: =D27 -> 156 | E128: =E127 -> -0.015 | F128: =F127 -> -0.015 | G128: =G127 -> -0.015 | H128: =B128*10000+D128 -> 10156 | I128: {=INDEX(I$14:I$114,$A128+1)+SUMPRODUCT(TRANSPOSE($E128:$G128),I$7:I$9)} -> 0.018280949 | J128: {=INDEX(J$14:J$114,$A128+1)+SUMPRODUCT(TRANSPOSE($E128:$G128),J$7:J$9)} -> 0.018003014 | K128: {=INDEX(K$14:K$114,$A128+1)+SUMPRODUCT(TRANSPOSE($E128:$G128),K$7:K$9)} -> 0.017723409 | L128: {=INDEX(L$14:L$114,$A128+1)+SUMPRODUCT(TRANSPOSE($E128:$G128),L$7:L$9)} -> 0.017442909 | M128: {=INDEX(M$14:M$114,$A128+1)+SUMPRODUCT(TRANSPOSE($E128:$G128),M$7:M$9)} -> 0.01716217 | N128: {=INDEX(N$14:N$114,$A128+1)+SUMPRODUCT(TRANSPOSE($E128:$G128),N$7:N$9)} -> 0.016881742 | O128: {=INDEX(O$14:O$114,$A128+1)+SUMPRODUCT(TRANSPOSE($E128:$G128),O$7:O$9)} -> 0.016602081 | P128: {=INDEX(P$14:P$114,$A128+1)+SUMPRODUCT(TRANSPOSE($E128:$G128),P$7:P$9)} -> 0.015885291 | ... DD128: {=INDEX(DD$14:DD$114,$A128+1)+SUMPRODUCT(TRANSPOSE($E128:$G128),DD$7:DD$9)} -> 0.0237163
...

Sheet Scenarios
A1: Scenario # | B1: Time | C1: Currency | D1: 30 Day | E1: 90 Day | F1: 6 Month | G1: 1 Year | H1: 2 Year | I1: 3 year | J1: 4 Year | K1: 5 Year | L1: 6 Year | M1: 7 Year | N1: 8 Year | O1: 9 Year | P1: 10 Year | Q1: 20 Year | R1: 30 Year | S1: 40 Year | T1: 50 Year | U1: 60 Year | V1: 70 Year | W1: 80 Year | X1: 90 Year | Y1: 100 Year | Z1: Equity | AA1: Inflation | AB1: Real Estate | AC1: Fixed Income
A2: 0 | B2: 0 | C2: =Currency -> USD | D2: =VLOOKUP($A2*10000+$B2,'Reduced Spot Curves'!$H:$DD,VLOOKUP(D$1,'Rate Mapping'!$A:$B,2,FALSE)+1,TRUE)*(12-MOD($B2,12))/12+VLOOKUP($A2*10000+$B2+12,'Reduced Spot Curves'!$H:$DD,VLOOKUP(D$1,'Rate Mapping'!$A:$B,2,FALSE)+1,TRUE)*(MOD($B2,12))/12 -> 0.044490912 | E2: =VLOOKUP($A2*10000+$B2,'Reduced Spot Curves'!$H:$DD,VLOOKUP(E$1,'Rate Mapping'!$A:$B,2,FALSE)+1,TRUE)*(12-MOD($B2,12))/12+VLOOKUP($A2*10000+$B2+12,'Reduced Spot Curves'!$H:$DD,VLOOKUP(E$1,'Rate Mapping'!$A:$B,2,FALSE)+1,TRUE)*(MOD($B2,12))/12 -> 0.044490912 | F2: =VLOOKUP($A2*10000+$B2,'Reduced Spot Curves'!$H:$DD,VLOOKUP(F$1,'Rate Mapping'!$A:$B,2,FALSE)+1,TRUE)*(12-MOD($B2,12))/12+VLOOKUP($A2*10000+$B2+12,'Reduced Spot Curves'!$H:$DD,VLOOKUP(F$1,'Rate Mapping'!$A:$B,2,FALSE)+1,TRUE)*(MOD($B2,12))/12 -> 0.044490912 | G2: =VLOOKUP($A2*10000+$B2,'Reduced Spot Curves'!$H:$DD,VLOOKUP(G$1,'Rate Mapping'!$A:$B,2,FALSE)+1,TRUE)*(12-MOD($B2,12))/12+VLOOKUP($A2*10000+$B2+12,'Reduced Spot Curves'!$H:$DD,VLOOKUP(G$1,'Rate Mapping'!$A:$B,2,FALSE)+1,TRUE)*(MOD($B2,12))/12 -> 0.044490912 | H2: =VLOOKUP($A2*10000+$B2,'Reduced Spot Curves'!$H:$DD,VLOOKUP(H$1,'Rate Mapping'!$A:$B,2,FALSE)+1,TRUE)*(12-MOD($B2,12))/12+VLOOKUP($A2*10000+$B2+12,'Reduced Spot Curves'!$H:$DD,VLOOKUP(H$1,'Rate Mapping'!$A:$B,2,FALSE)+1,TRUE)*(MOD($B2,12))/12 -> 0.043834498 | I2: =VLOOKUP($A2*10000+$B2,'Reduced Spot Curves'!$H:$DD,VLOOKUP(I$1,'Rate Mapping'!$A:$B,2,FALSE)+1,TRUE)*(12-MOD($B2,12))/12+VLOOKUP($A2*10000+$B2+12,'Reduced Spot Curves'!$H:$DD,VLOOKUP(I$1,'Rate Mapping'!$A:$B,2,FALSE)+1,TRUE)*(MOD($B2,12))/12 -> 0.041829148 | J2: =VLOOKUP($A2*10000+$B2,'Reduced Spot Curves'!$H:$DD,VLOOKUP(J$1,'Rate Mapping'!$A:$B,2,FALSE)+1,TRUE)*(12-MOD($B2,12))/12+VLOOKUP($A2*10000+$B2+12,'Reduced Spot Curves'!$H:$DD,VLOOKUP(J$1,'Rate Mapping'!$A:$B,2,FALSE)+1,TRUE)*(MOD($B2,12))/12 -> 0.04063536 | K2: =VLOOKUP($A2*10000+$B2,'Reduced Spot Curves'!$H:$DD,VLOOKUP(K$1,'Rate Mapping'!$A:$B,2,FALSE)+1,TRUE)*(12-MOD($B2,12))/12+VLOOKUP($A2*10000+$B2+12,'Reduced Spot Curves'!$H:$DD,VLOOKUP(K$1,'Rate Mapping'!$A:$B,2,FALSE)+1,TRUE)*(MOD($B2,12))/12 -> 0.039398721 | ... Y2: =VLOOKUP($A2*10000+$B2,'Reduced Spot Curves'!$H:$DD,VLOOKUP(Y$1,'Rate Mapping'!$A:$B,2,FALSE)+1,TRUE)*(12-MOD($B2,12))/12+VLOOKUP($A2*10000+$B2+12,'Reduced Spot Curves'!$H:$DD,VLOOKUP(Y$1,'Rate Mapping'!$A:$B,2,FALSE)+1,TRUE)*(MOD($B2,12))/12 -> 0.0387163 | Z2: 0.06 | AA2: 0 | AB2: 0 | AC2: 0
A3: 0 | B3: 3 | C3: =Currency -> USD | D3: =VLOOKUP($A3*10000+$B3,'Reduced Spot Curves'!$H:$DD,VLOOKUP(D$1,'Rate Mapping'!$A:$B,2,FALSE)+1,TRUE)*(12-MOD($B3,12))/12+VLOOKUP($A3*10000+$B3+12,'Reduced Spot Curves'!$H:$DD,VLOOKUP(D$1,'Rate Mapping'!$A:$B,2,FALSE)+1,TRUE)*(MOD($B3,12))/12 -> 0.044162808 | E3: =VLOOKUP($A3*10000+$B3,'Reduced Spot Curves'!$H:$DD,VLOOKUP(E$1,'Rate Mapping'!$A:$B,2,FALSE)+1,TRUE)*(12-MOD($B3,12))/12+VLOOKUP($A3*10000+$B3+12,'Reduced Spot Curves'!$H:$DD,VLOOKUP(E$1,'Rate Mapping'!$A:$B,2,FALSE)+1,TRUE)*(MOD($B3,12))/12 -> 0.044162808 | F3: =VLOOKUP($A3*10000+$B3,'Reduced Spot Curves'!$H:$DD,VLOOKUP(F$1,'Rate Mapping'!$A:$B,2,FALSE)+1,TRUE)*(12-MOD($B3,12))/12+VLOOKUP($A3*10000+$B3+12,'Reduced Spot Curves'!$H:$DD,VLOOKUP(F$1,'Rate Mapping'!$A:$B,2,FALSE)+1,TRUE)*(MOD($B3,12))/12 -> 0.044162808 | G3: =VLOOKUP($A3*10000+$B3,'Reduced Spot Curves'!$H:$DD,VLOOKUP(G$1,'Rate Mapping'!$A:$B,2,FALSE)+1,TRUE)*(12-MOD($B3,12))/12+VLOOKUP($A3*10000+$B3+12,'Reduced Spot Curves'!$H:$DD,VLOOKUP(G$1,'Rate Mapping'!$A:$B,2,FALSE)+1,TRUE)*(MOD($B3,12))/12 -> 0.044162808 | H3: =VLOOKUP($A3*10000+$B3,'Reduced Spot Curves'!$H:$DD,VLOOKUP(H$1,'Rate Mapping'!$A:$B,2,FALSE)+1,TRUE)*(12-MOD($B3,12))/12+VLOOKUP($A3*10000+$B3+12,'Reduced Spot Curves'!$H:$DD,VLOOKUP(H$1,'Rate Mapping'!$A:$B,2,FALSE)+1,TRUE)*(MOD($B3,12))/12 -> 0.043001076 | I3: =VLOOKUP($A3*10000+$B3,'Reduced Spot Curves'!$H:$DD,VLOOKUP(I$1,'Rate Mapping'!$A:$B,2,FALSE)+1,TRUE)*(12-MOD($B3,12))/12+VLOOKUP($A3*10000+$B3+12,'Reduced Spot Curves'!$H:$DD,VLOOKUP(I$1,'Rate Mapping'!$A:$B,2,FALSE)+1,TRUE)*(MOD($B3,12))/12 -> 0.041210196 | J3: =VLOOKUP($A3*10000+$B3,'Reduced Spot Curves'!$H:$DD,VLOOKUP(J$1,'Rate Mapping'!$A:$B,2,FALSE)+1,TRUE)*(12-MOD($B3,12))/12+VLOOKUP($A3*10000+$B3+12,'Reduced Spot Curves'!$H:$DD,VLOOKUP(J$1,'Rate Mapping'!$A:$B,2,FALSE)+1,TRUE)*(MOD($B3,12))/12 -> 0.040008909 | K3: =VLOOKUP($A3*10000+$B3,'Reduced Spot Curves'!$H:$DD,VLOOKUP(K$1,'Rate Mapping'!$A:$B,2,FALSE)+1,TRUE)*(12-MOD($B3,12))/12+VLOOKUP($A3*10000+$B3+12,'Reduced Spot Curves'!$H:$DD,VLOOKUP(K$1,'Rate Mapping'!$A:$B,2,FALSE)+1,TRUE)*(MOD($B3,12))/12 -> 0.038929823 | ... Y3: =VLOOKUP($A3*10000+$B3,'Reduced Spot Curves'!$H:$DD,VLOOKUP(Y$1,'Rate Mapping'!$A:$B,2,FALSE)+1,TRUE)*(12-MOD($B3,12))/12+VLOOKUP($A3*10000+$B3+12,'Reduced Spot Curves'!$H:$DD,VLOOKUP(Y$1,'Rate Mapping'!$A:$B,2,FALSE)+1,TRUE)*(MOD($B3,12))/12 -> 0.0387163 | Z3: =Z2 -> 0.06 | AA3: =AA2 -> 0 | AB3: =AB2 -> 0 | AC3: =AC2 -> 0
A4: 0 | B4: 6 | C4: =Currency -> USD | D4: =VLOOKUP($A4*10000+$B4,'Reduced Spot Curves'!$H:$DD,VLOOKUP(D$1,'Rate Mapping'!$A:$B,2,FALSE)+1,TRUE)*(12-MOD($B4,12))/12+VLOOKUP($A4*10000+$B4+12,'Reduced Spot Curves'!$H:$DD,VLOOKUP(D$1,'Rate Mapping'!$A:$B,2,FALSE)+1,TRUE)*(MOD($B4,12))/12 -> 0.043834704 | E4: =VLOOKUP($A4*10000+$B4,'Reduced Spot Curves'!$H:$DD,VLOOKUP(E$1,'Rate Mapping'!$A:$B,2,FALSE)+1,TRUE)*(12-MOD($B4,12))/12+VLOOKUP($A4*10000+$B4+12,'Reduced Spot Curves'!$H:$DD,VLOOKUP(E$1,'Rate Mapping'!$A:$B,2,FALSE)+1,TRUE)*(MOD($B4,12))/12 -> 0.043834704 | F4: =VLOOKUP($A4*10000+$B4,'Reduced Spot Curves'!$H:$DD,VLOOKUP(F$1,'Rate Mapping'!$A:$B,2,FALSE)+1,TRUE)*(12-MOD($B4,12))/12+VLOOKUP($A4*10000+$B4+12,'Reduced Spot Curves'!$H:$DD,VLOOKUP(F$1,'Rate Mapping'!$A:$B,2,FALSE)+1,TRUE)*(MOD($B4,12))/12 -> 0.043834704 | G4: =VLOOKUP($A4*10000+$B4,'Reduced Spot Curves'!$H:$DD,VLOOKUP(G$1,'Rate Mapping'!$A:$B,2,FALSE)+1,TRUE)*(12-MOD($B4,12))/12+VLOOKUP($A4*10000+$B4+12,'Reduced Spot Curves'!$H:$DD,VLOOKUP(G$1,'Rate Mapping'!$A:$B,2,FALSE)+1,TRUE)*(MOD($B4,12))/12 -> 0.043834704 | H4: =VLOOKUP($A4*10000+$B4,'Reduced Spot Curves'!$H:$DD,VLOOKUP(H$1,'Rate Mapping'!$A:$B,2,FALSE)+1,TRUE)*(12-MOD($B4,12))/12+VLOOKUP($A4*10000+$B4+12,'Reduced Spot Curves'!$H:$DD,VLOOKUP(H$1,'Rate Mapping'!$A:$B,2,FALSE)+1,TRUE)*(MOD($B4,12))/12 -> 0.042167654 | I4: =VLOOKUP($A4*10000+$B4,'Reduced Spot Curves'!$H:$DD,VLOOKUP(I$1,'Rate Mapping'!$A:$B,2,FALSE)+1,TRUE)*(12-MOD($B4,12))/12+VLOOKUP($A4*10000+$B4+12,'Reduced Spot Curves'!$H:$DD,VLOOKUP(I$1,'Rate Mapping'!$A:$B,2,FALSE)+1,TRUE)*(MOD($B4,12))/12 -> 0.040591245 | J4: =VLOOKUP($A4*10000+$B4,'Reduced Spot Curves'!$H:$DD,VLOOKUP(J$1,'Rate Mapping'!$A:$B,2,FALSE)+1,TRUE)*(12-MOD($B4,12))/12+VLOOKUP($A4*10000+$B4+12,'Reduced Spot Curves'!$H:$DD,VLOOKUP(J$1,'Rate Mapping'!$A:$B,2,FALSE)+1,TRUE)*(MOD($B4,12))/12 -> 0.039382459 | K4: =VLOOKUP($A4*10000+$B4,'Reduced Spot Curves'!$H:$DD,VLOOKUP(K$1,'Rate Mapping'!$A:$B,2,FALSE)+1,TRUE)*(12-MOD($B4,12))/12+VLOOKUP($A4*10000+$B4+12,'Reduced Spot Curves'!$H:$DD,VLOOKUP(K$1,'Rate Mapping'!$A:$B,2,FALSE)+1,TRUE)*(MOD($B4,12))/12 -> 0.038460926 | ... Y4: =VLOOKUP($A4*10000+$B4,'Reduced Spot Curves'!$H:$DD,VLOOKUP(Y$1,'Rate Mapping'!$A:$B,2,FALSE)+1,TRUE)*(12-MOD($B4,12))/12+VLOOKUP($A4*10000+$B4+12,'Reduced Spot Curves'!$H:$DD,VLOOKUP(Y$1,'Rate Mapping'!$A:$B,2,FALSE)+1,TRUE)*(MOD($B4,12))/12 -> 0.0387163 | Z4: =Z3 -> 0.06 | AA4: =AA3 -> 0 | AB4: =AB3 -> 0 | AC4: =AC3 -> 0
A5: 0 | B5: 9 | C5: =Currency -> USD | D5: =VLOOKUP($A5*10000+$B5,'Reduced Spot Curves'!$H:$DD,VLOOKUP(D$1,'Rate Mapping'!$A:$B,2,FALSE)+1,TRUE)*(12-MOD($B5,12))/12+VLOOKUP($A5*10000+$B5+12,'Reduced Spot Curves'!$H:$DD,VLOOKUP(D$1,'Rate Mapping'!$A:$B,2,FALSE)+1,TRUE)*(MOD($B5,12))/12 -> 0.0435066 | E5: =VLOOKUP($A5*10000+$B5,'Reduced Spot Curves'!$H:$DD,VLOOKUP(E$1,'Rate Mapping'!$A:$B,2,FALSE)+1,TRUE)*(12-MOD($B5,12))/12+VLOOKUP($A5*10000+$B5+12,'Reduced Spot Curves'!$H:$DD,VLOOKUP(E$1,'Rate Mapping'!$A:$B,2,FALSE)+1,TRUE)*(MOD($B5,12))/12 -> 0.0435066 | F5: =VLOOKUP($A5*10000+$B5,'Reduced Spot Curves'!$H:$DD,VLOOKUP(F$1,'Rate Mapping'!$A:$B,2,FALSE)+1,TRUE)*(12-MOD($B5,12))/12+VLOOKUP($A5*10000+$B5+12,'Reduced Spot Curves'!$H:$DD,VLOOKUP(F$1,'Rate Mapping'!$A:$B,2,FALSE)+1,TRUE)*(MOD($B5,12))/12 -> 0.0435066 | G5: =VLOOKUP($A5*10000+$B5,'Reduced Spot Curves'!$H:$DD,VLOOKUP(G$1,'Rate Mapping'!$A:$B,2,FALSE)+1,TRUE)*(12-MOD($B5,12))/12+VLOOKUP($A5*10000+$B5+12,'Reduced Spot Curves'!$H:$DD,VLOOKUP(G$1,'Rate Mapping'!$A:$B,2,FALSE)+1,TRUE)*(MOD($B5,12))/12 -> 0.0435066 | H5: =VLOOKUP($A5*10000+$B5,'Reduced Spot Curves'!$H:$DD,VLOOKUP(H$1,'Rate Mapping'!$A:$B,2,FALSE)+1,TRUE)*(12-MOD($B5,12))/12+VLOOKUP($A5*10000+$B5+12,'Reduced Spot Curves'!$H:$DD,VLOOKUP(H$1,'Rate Mapping'!$A:$B,2,FALSE)+1,TRUE)*(MOD($B5,12))/12 -> 0.041334232 | I5: =VLOOKUP($A5*10000+$B5,'Reduced Spot Curves'!$H:$DD,VLOOKUP(I$1,'Rate Mapping'!$A:$B,2,FALSE)+1,TRUE)*(12-MOD($B5,12))/12+VLOOKUP($A5*10000+$B5+12,'Reduced Spot Curves'!$H:$DD,VLOOKUP(I$1,'Rate Mapping'!$A:$B,2,FALSE)+1,TRUE)*(MOD($B5,12))/12 -> 0.039972293 | J5: =VLOOKUP($A5*10000+$B5,'Reduced Spot Curves'!$H:$DD,VLOOKUP(J$1,'Rate Mapping'!$A:$B,2,FALSE)+1,TRUE)*(12-MOD($B5,12))/12+VLOOKUP($A5*10000+$B5+12,'Reduced Spot Curves'!$H:$DD,VLOOKUP(J$1,'Rate Mapping'!$A:$B,2,FALSE)+1,TRUE)*(MOD($B5,12))/12 -> 0.038756008 | K5: =VLOOKUP($A5*10000+$B5,'Reduced Spot Curves'!$H:$DD,VLOOKUP(K$1,'Rate Mapping'!$A:$B,2,FALSE)+1,TRUE)*(12-MOD($B5,12))/12+VLOOKUP($A5*10000+$B5+12,'Reduced Spot Curves'!$H:$DD,VLOOKUP(K$1,'Rate Mapping'!$A:$B,2,FALSE)+1,TRUE)*(MOD($B5,12))/12 -> 0.037992028 | ... Y5: =VLOOKUP($A5*10000+$B5,'Reduced Spot Curves'!$H:$DD,VLOOKUP(Y$1,'Rate Mapping'!$A:$B,2,FALSE)+1,TRUE)*(12-MOD($B5,12))/12+VLOOKUP($A5*10000+$B5+12,'Reduced Spot Curves'!$H:$DD,VLOOKUP(Y$1,'Rate Mapping'!$A:$B,2,FALSE)+1,TRUE)*(MOD($B5,12))/12 -> 0.0387163 | Z5: =Z4 -> 0.06 | AA5: =AA4 -> 0 | AB5: =AB4 -> 0 | AC5: =AC4 -> 0
A6: 0 | B6: 12 | C6: =Currency -> USD | D6: =VLOOKUP($A6*10000+$B6,'Reduced Spot Curves'!$H:$DD,VLOOKUP(D$1,'Rate Mapping'!$A:$B,2,FALSE)+1,TRUE)*(12-MOD($B6,12))/12+VLOOKUP($A6*10000+$B6+12,'Reduced Spot Curves'!$H:$DD,VLOOKUP(D$1,'Rate Mapping'!$A:$B,2,FALSE)+1,TRUE)*(MOD($B6,12))/12 -> 0.043178496 | E6: =VLOOKUP($A6*10000+$B6,'Reduced Spot Curves'!$H:$DD,VLOOKUP(E$1,'Rate Mapping'!$A:$B,2,FALSE)+1,TRUE)*(12-MOD($B6,12))/12+VLOOKUP($A6*10000+$B6+12,'Reduced Spot Curves'!$H:$DD,VLOOKUP(E$1,'Rate Mapping'!$A:$B,2,FALSE)+1,TRUE)*(MOD($B6,12))/12 -> 0.043178496 | F6: =VLOOKUP($A6*10000+$B6,'Reduced Spot Curves'!$H:$DD,VLOOKUP(F$1,'Rate Mapping'!$A:$B,2,FALSE)+1,TRUE)*(12-MOD($B6,12))/12+VLOOKUP($A6*10000+$B6+12,'Reduced Spot Curves'!$H:$DD,VLOOKUP(F$1,'Rate Mapping'!$A:$B,2,FALSE)+1,TRUE)*(MOD($B6,12))/12 -> 0.043178496 | G6: =VLOOKUP($A6*10000+$B6,'Reduced Spot Curves'!$H:$DD,VLOOKUP(G$1,'Rate Mapping'!$A:$B,2,FALSE)+1,TRUE)*(12-MOD($B6,12))/12+VLOOKUP($A6*10000+$B6+12,'Reduced Spot Curves'!$H:$DD,VLOOKUP(G$1,'Rate Mapping'!$A:$B,2,FALSE)+1,TRUE)*(MOD($B6,12))/12 -> 0.043178496 | H6: =VLOOKUP($A6*10000+$B6,'Reduced Spot Curves'!$H:$DD,VLOOKUP(H$1,'Rate Mapping'!$A:$B,2,FALSE)+1,TRUE)*(12-MOD($B6,12))/12+VLOOKUP($A6*10000+$B6+12,'Reduced Spot Curves'!$H:$DD,VLOOKUP(H$1,'Rate Mapping'!$A:$B,2,FALSE)+1,TRUE)*(MOD($B6,12))/12 -> 0.04050081 | I6: =VLOOKUP($A6*10000+$B6,'Reduced Spot Curves'!$H:$DD,VLOOKUP(I$1,'Rate Mapping'!$A:$B,2,FALSE)+1,TRUE)*(12-MOD($B6,12))/12+VLOOKUP($A6*10000+$B6+12,'Reduced Spot Curves'!$H:$DD,VLOOKUP(I$1,'Rate Mapping'!$A:$B,2,FALSE)+1,TRUE)*(MOD($B6,12))/12 -> 0.039353342 | J6: =VLOOKUP($A6*10000+$B6,'Reduced Spot Curves'!$H:$DD,VLOOKUP(J$1,'Rate Mapping'!$A:$B,2,FALSE)+1,TRUE)*(12-MOD($B6,12))/12+VLOOKUP($A6*10000+$B6+12,'Reduced Spot Curves'!$H:$DD,VLOOKUP(J$1,'Rate Mapping'!$A:$B,2,FALSE)+1,TRUE)*(MOD($B6,12))/12 -> 0.038129557 | K6: =VLOOKUP($A6*10000+$B6,'Reduced Spot Curves'!$H:$DD,VLOOKUP(K$1,'Rate Mapping'!$A:$B,2,FALSE)+1,TRUE)*(12-MOD($B6,12))/12+VLOOKUP($A6*10000+$B6+12,'Reduced Spot Curves'!$H:$DD,VLOOKUP(K$1,'Rate Mapping'!$A:$B,2,FALSE)+1,TRUE)*(MOD($B6,12))/12 -> 0.037523131 | ... Y6: =VLOOKUP($A6*10000+$B6,'Reduced Spot Curves'!$H:$DD,VLOOKUP(Y$1,'Rate Mapping'!$A:$B,2,FALSE)+1,TRUE)*(12-MOD($B6,12))/12+VLOOKUP($A6*10000+$B6+12,'Reduced Spot Curves'!$H:$DD,VLOOKUP(Y$1,'Rate Mapping'!$A:$B,2,FALSE)+1,TRUE)*(MOD($B6,12))/12 -> 0.0387163 | Z6: =Z5 -> 0.06 | AA6: =AA5 -> 0 | AB6: =AB5 -> 0 | AC6: =AC5 -> 0
A7: 0 | B7: 15 | C7: =Currency -> USD | D7: =VLOOKUP($A7*10000+$B7,'Reduced Spot Curves'!$H:$DD,VLOOKUP(D$1,'Rate Mapping'!$A:$B,2,FALSE)+1,TRUE)*(12-MOD($B7,12))/12+VLOOKUP($A7*10000+$B7+12,'Reduced Spot Curves'!$H:$DD,VLOOKUP(D$1,'Rate Mapping'!$A:$B,2,FALSE)+1,TRUE)*(MOD($B7,12))/12 -> 0.041841372 | E7: =VLOOKUP($A7*10000+$B7,'Reduced Spot Curves'!$H:$DD,VLOOKUP(E$1,'Rate Mapping'!$A:$B,2,FALSE)+1,TRUE)*(12-MOD($B7,12))/12+VLOOKUP($A7*10000+$B7+12,'Reduced Spot Curves'!$H:$DD,VLOOKUP(E$1,'Rate Mapping'!$A:$B,2,FALSE)+1,TRUE)*(MOD($B7,12))/12 -> 0.041841372 | F7: =VLOOKUP($A7*10000+$B7,'Reduced Spot Curves'!$H:$DD,VLOOKUP(F$1,'Rate Mapping'!$A:$B,2,FALSE)+1,TRUE)*(12-MOD($B7,12))/12+VLOOKUP($A7*10000+$B7+12,'Reduced Spot Curves'!$H:$DD,VLOOKUP(F$1,'Rate Mapping'!$A:$B,2,FALSE)+1,TRUE)*(MOD($B7,12))/12 -> 0.041841372 | G7: =VLOOKUP($A7*10000+$B7,'Reduced Spot Curves'!$H:$DD,VLOOKUP(G$1,'Rate Mapping'!$A:$B,2,FALSE)+1,TRUE)*(12-MOD($B7,12))/12+VLOOKUP($A7*10000+$B7+12,'Reduced Spot Curves'!$H:$DD,VLOOKUP(G$1,'Rate Mapping'!$A:$B,2,FALSE)+1,TRUE)*(MOD($B7,12))/12 -> 0.041841372 | H7: =VLOOKUP($A7*10000+$B7,'Reduced Spot Curves'!$H:$DD,VLOOKUP(H$1,'Rate Mapping'!$A:$B,2,FALSE)+1,TRUE)*(12-MOD($B7,12))/12+VLOOKUP($A7*10000+$B7+12,'Reduced Spot Curves'!$H:$DD,VLOOKUP(H$1,'Rate Mapping'!$A:$B,2,FALSE)+1,TRUE)*(MOD($B7,12))/12 -> 0.039737115 | I7: =VLOOKUP($A7*10000+$B7,'Reduced Spot Curves'!$H:$DD,VLOOKUP(I$1,'Rate Mapping'!$A:$B,2,FALSE)+1,TRUE)*(12-MOD($B7,12))/12+VLOOKUP($A7*10000+$B7+12,'Reduced Spot Curves'!$H:$DD,VLOOKUP(I$1,'Rate Mapping'!$A:$B,2,FALSE)+1,TRUE)*(MOD($B7,12))/12 -> 0.03862801 | J7: =VLOOKUP($A7*10000+$B7,'Reduced Spot Curves'!$H:$DD,VLOOKUP(J$1,'Rate Mapping'!$A:$B,2,FALSE)+1,TRUE)*(12-MOD($B7,12))/12+VLOOKUP($A7*10000+$B7+12,'Reduced Spot Curves'!$H:$DD,VLOOKUP(J$1,'Rate Mapping'!$A:$B,2,FALSE)+1,TRUE)*(MOD($B7,12))/12 -> 0.037625689 | K7: =VLOOKUP($A7*10000+$B7,'Reduced Spot Curves'!$H:$DD,VLOOKUP(K$1,'Rate Mapping'!$A:$B,2,FALSE)+1,TRUE)*(12-MOD($B7,12))/12+VLOOKUP($A7*10000+$B7+12,'Reduced Spot Curves'!$H:$DD,VLOOKUP(K$1,'Rate Mapping'!$A:$B,2,FALSE)+1,TRUE)*(MOD($B7,12))/12 -> 0.03703697 | ... Y7: =VLOOKUP($A7*10000+$B7,'Reduced Spot Curves'!$H:$DD,VLOOKUP(Y$1,'Rate Mapping'!$A:$B,2,FALSE)+1,TRUE)*(12-MOD($B7,12))/12+VLOOKUP($A7*10000+$B7+12,'Reduced Spot Curves'!$H:$DD,VLOOKUP(Y$1,'Rate Mapping'!$A:$B,2,FALSE)+1,TRUE)*(MOD($B7,12))/12 -> 0.0387163 | Z7: =Z6 -> 0.06 | AA7: =AA6 -> 0 | AB7: =AB6 -> 0 | AC7: =AC6 -> 0
A8: 0 | B8: 18 | C8: =Currency -> USD | D8: =VLOOKUP($A8*10000+$B8,'Reduced Spot Curves'!$H:$DD,VLOOKUP(D$1,'Rate Mapping'!$A:$B,2,FALSE)+1,TRUE)*(12-MOD($B8,12))/12+VLOOKUP($A8*10000+$B8+12,'Reduced Spot Curves'!$H:$DD,VLOOKUP(D$1,'Rate Mapping'!$A:$B,2,FALSE)+1,TRUE)*(MOD($B8,12))/12 -> 0.040504247 | E8: =VLOOKUP($A8*10000+$B8,'Reduced Spot Curves'!$H:$DD,VLOOKUP(E$1,'Rate Mapping'!$A:$B,2,FALSE)+1,TRUE)*(12-MOD($B8,12))/12+VLOOKUP($A8*10000+$B8+12,'Reduced Spot Curves'!$H:$DD,VLOOKUP(E$1,'Rate Mapping'!$A:$B,2,FALSE)+1,TRUE)*(MOD($B8,12))/12 -> 0.040504247 | F8: =VLOOKUP($A8*10000+$B8,'Reduced Spot Curves'!$H:$DD,VLOOKUP(F$1,'Rate Mapping'!$A:$B,2,FALSE)+1,TRUE)*(12-MOD($B8,12))/12+VLOOKUP($A8*10000+$B8+12,'Reduced Spot Curves'!$H:$DD,VLOOKUP(F$1,'Rate Mapping'!$A:$B,2,FALSE)+1,TRUE)*(MOD($B8,12))/12 -> 0.040504247 | G8: =VLOOKUP($A8*10000+$B8,'Reduced Spot Curves'!$H:$DD,VLOOKUP(G$1,'Rate Mapping'!$A:$B,2,FALSE)+1,TRUE)*(12-MOD($B8,12))/12+VLOOKUP($A8*10000+$B8+12,'Reduced Spot Curves'!$H:$DD,VLOOKUP(G$1,'Rate Mapping'!$A:$B,2,FALSE)+1,TRUE)*(MOD($B8,12))/12 -> 0.040504247 | H8: =VLOOKUP($A8*10000+$B8,'Reduced Spot Curves'!$H:$DD,VLOOKUP(H$1,'Rate Mapping'!$A:$B,2,FALSE)+1,TRUE)*(12-MOD($B8,12))/12+VLOOKUP($A8*10000+$B8+12,'Reduced Spot Curves'!$H:$DD,VLOOKUP(H$1,'Rate Mapping'!$A:$B,2,FALSE)+1,TRUE)*(MOD($B8,12))/12 -> 0.038973419 | I8: =VLOOKUP($A8*10000+$B8,'Reduced Spot Curves'!$H:$DD,VLOOKUP(I$1,'Rate Mapping'!$A:$B,2,FALSE)+1,TRUE)*(12-MOD($B8,12))/12+VLOOKUP($A8*10000+$B8+12,'Reduced Spot Curves'!$H:$DD,VLOOKUP(I$1,'Rate Mapping'!$A:$B,2,FALSE)+1,TRUE)*(MOD($B8,12))/12 -> 0.037902678 | J8: =VLOOKUP($A8*10000+$B8,'Reduced Spot Curves'!$H:$DD,VLOOKUP(J$1,'Rate Mapping'!$A:$B,2,FALSE)+1,TRUE)*(12-MOD($B8,12))/12+VLOOKUP($A8*10000+$B8+12,'Reduced Spot Curves'!$H:$DD,VLOOKUP(J$1,'Rate Mapping'!$A:$B,2,FALSE)+1,TRUE)*(MOD($B8,12))/12 -> 0.037121822 | K8: =VLOOKUP($A8*10000+$B8,'Reduced Spot Curves'!$H:$DD,VLOOKUP(K$1,'Rate Mapping'!$A:$B,2,FALSE)+1,TRUE)*(12-MOD($B8,12))/12+VLOOKUP($A8*10000+$B8+12,'Reduced Spot Curves'!$H:$DD,VLOOKUP(K$1,'Rate Mapping'!$A:$B,2,FALSE)+1,TRUE)*(MOD($B8,12))/12 -> 0.036550809 | ... Y8: =VLOOKUP($A8*10000+$B8,'Reduced Spot Curves'!$H:$DD,VLOOKUP(Y$1,'Rate Mapping'!$A:$B,2,FALSE)+1,TRUE)*(12-MOD($B8,12))/12+VLOOKUP($A8*10000+$B8+12,'Reduced Spot Curves'!$H:$DD,VLOOKUP(Y$1,'Rate Mapping'!$A:$B,2,FALSE)+1,TRUE)*(MOD($B8,12))/12 -> 0.0387163 | Z8: =Z7 -> 0.06 | AA8: =AA7 -> 0 | AB8: =AB7 -> 0 | AC8: =AC7 -> 0
A9: 0 | B9: 21 | C9: =Currency -> USD | D9: =VLOOKUP($A9*10000+$B9,'Reduced Spot Curves'!$H:$DD,VLOOKUP(D$1,'Rate Mapping'!$A:$B,2,FALSE)+1,TRUE)*(12-MOD($B9,12))/12+VLOOKUP($A9*10000+$B9+12,'Reduced Spot Curves'!$H:$DD,VLOOKUP(D$1,'Rate Mapping'!$A:$B,2,FALSE)+1,TRUE)*(MOD($B9,12))/12 -> 0.039167122 | E9: =VLOOKUP($A9*10000+$B9,'Reduced Spot Curves'!$H:$DD,VLOOKUP(E$1,'Rate Mapping'!$A:$B,2,FALSE)+1,TRUE)*(12-MOD($B9,12))/12+VLOOKUP($A9*10000+$B9+12,'Reduced Spot Curves'!$H:$DD,VLOOKUP(E$1,'Rate Mapping'!$A:$B,2,FALSE)+1,TRUE)*(MOD($B9,12))/12 -> 0.039167122 | F9: =VLOOKUP($A9*10000+$B9,'Reduced Spot Curves'!$H:$DD,VLOOKUP(F$1,'Rate Mapping'!$A:$B,2,FALSE)+1,TRUE)*(12-MOD($B9,12))/12+VLOOKUP($A9*10000+$B9+12,'Reduced Spot Curves'!$H:$DD,VLOOKUP(F$1,'Rate Mapping'!$A:$B,2,FALSE)+1,TRUE)*(MOD($B9,12))/12 -> 0.039167122 | G9: =VLOOKUP($A9*10000+$B9,'Reduced Spot Curves'!$H:$DD,VLOOKUP(G$1,'Rate Mapping'!$A:$B,2,FALSE)+1,TRUE)*(12-MOD($B9,12))/12+VLOOKUP($A9*10000+$B9+12,'Reduced Spot Curves'!$H:$DD,VLOOKUP(G$1,'Rate Mapping'!$A:$B,2,FALSE)+1,TRUE)*(MOD($B9,12))/12 -> 0.039167122 | H9: =VLOOKUP($A9*10000+$B9,'Reduced Spot Curves'!$H:$DD,VLOOKUP(H$1,'Rate Mapping'!$A:$B,2,FALSE)+1,TRUE)*(12-MOD($B9,12))/12+VLOOKUP($A9*10000+$B9+12,'Reduced Spot Curves'!$H:$DD,VLOOKUP(H$1,'Rate Mapping'!$A:$B,2,FALSE)+1,TRUE)*(MOD($B9,12))/12 -> 0.038209723 | I9: =VLOOKUP($A9*10000+$B9,'Reduced Spot Curves'!$H:$DD,VLOOKUP(I$1,'Rate Mapping'!$A:$B,2,FALSE)+1,TRUE)*(12-MOD($B9,12))/12+VLOOKUP($A9*10000+$B9+12,'Reduced Spot Curves'!$H:$DD,VLOOKUP(I$1,'Rate Mapping'!$A:$B,2,FALSE)+1,TRUE)*(MOD($B9,12))/12 -> 0.037177346 | J9: =VLOOKUP($A9*10000+$B9,'Reduced Spot Curves'!$H:$DD,VLOOKUP(J$1,'Rate Mapping'!$A:$B,2,FALSE)+1,TRUE)*(12-MOD($B9,12))/12+VLOOKUP($A9*10000+$B9+12,'Reduced Spot Curves'!$H:$DD,VLOOKUP(J$1,'Rate Mapping'!$A:$B,2,FALSE)+1,TRUE)*(MOD($B9,12))/12 -> 0.036617954 | K9: =VLOOKUP($A9*10000+$B9,'Reduced Spot Curves'!$H:$DD,VLOOKUP(K$1,'Rate Mapping'!$A:$B,2,FALSE)+1,TRUE)*(12-MOD($B9,12))/12+VLOOKUP($A9*10000+$B9+12,'Reduced Spot Curves'!$H:$DD,VLOOKUP(K$1,'Rate Mapping'!$A:$B,2,FALSE)+1,TRUE)*(MOD($B9,12))/12 -> 0.036064648 | ... Y9: =VLOOKUP($A9*10000+$B9,'Reduced Spot Curves'!$H:$DD,VLOOKUP(Y$1,'Rate Mapping'!$A:$B,2,FALSE)+1,TRUE)*(12-MOD($B9,12))/12+VLOOKUP($A9*10000+$B9+12,'Reduced Spot Curves'!$H:$DD,VLOOKUP(Y$1,'Rate Mapping'!$A:$B,2,FALSE)+1,TRUE)*(MOD($B9,12))/12 -> 0.0387163 | Z9: =Z8 -> 0.06 | AA9: =AA8 -> 0 | AB9: =AB8 -> 0 | AC9: =AC8 -> 0
